Workbook

Sheet ALL
A1: Name | B1: Population | C1: Pronunciation | D1: IPA Use (https://ipa-reader.com/) | E1: Continent | F1: GDP (Nominal) | G1: Per (NOM) | H1: GDP (PPP) | I1: Per (PPP) | J1: Density | K1: Area (Km) | L1: Area (Mi) | M1: KTDI | N1: GDI | O1: Phone | P1: Domain | Q1: Capital | R1: Demonym | S1: Military NOM | T1: Military NOM USD | U1: Military PPP | V1: Military PPP USD | W1: Per GDP
A2: Raledria | B2: =SUM(J2*K2) -> 3.0111528e+08 | C2: rah-LED-ree-uh | D2: /ˌrɑːˈlɛd.ri.ə/ | E2: Atirha | F2: =SUM(G2*B2) -> 8579395623719 | G2: 28492.063 | H2: 8.5793956e+12 | I2: =sum(H2/B2) -> 28492.063 | J2: 127.8124 | K2: 2355916 | L2: =SUM(K2*0.386102) -> 909623.88 | M2: 0.942 | N2: 8.66 | O2: 20 | P2: .ral | Q2: Tirna | R2: Raledrian | S2: =SUM(F2*W2) -> 292557390769 | T2: =SUM(F2*W2*1.5) -> 438836086153 | U2: =SUM(H2*W2) -> 292557390769 | V2: =SUM(H2*W2*1.5) -> 438836086153 | W2: 0.0341
A3: Dahe | B3: =SUM(J3*K3) -> 8.9060132e+08 | C3: dah-HAY | D3: /dɑːˈheɪ/ | E3: Massir | F3: =SUM(G3*B3) -> 9578388947394 | G3: 10754.968 | H3: 1.8026609e+13 | I3: =sum(H3/B3) -> 20240.941 | J3: 201.0773 | K3: 4429149 | L3: =SUM(K3*0.386102) -> 1710103.3 | M3: 0.895 | N3: 6.21 | O3: 51 | P3: .dah | Q3: Fekunza | R3: Dahen | S3: =SUM(F3*W3) -> 289267346211 | T3: =SUM(F3*W3*1.5) -> 433901019317 | U3: =SUM(H3*W3) -> 544403590847 | V3: =SUM(H3*W3*1.5) -> 816605386271 | W3: 0.0302
A4: Pelugrotoa | B4: =SUM(J4*K4) -> 3.4752059e+08 | C4: peh-LOO-groh-toh-uh | D4: /pɛˈluː.groʊ.toʊ.ə/ | E4: Mahea | F4: =SUM(G4*B4) -> 4121980291974 | G4: 11861.111 | H4: 7.4607843e+12 | I4: =sum(H4/B4) -> 21468.611 | J4: 134.5993 | K4: 2581890 | L4: =SUM(K4*0.386102) -> 996872.89 | M4: 0.839 | N4: 2.33 | O4: 901 | P4: .pel | Q4: Thavrin | R4: Pelugrotoan | S4: =SUM(F4*W4) -> 176420756497 | T4: =SUM(F4*W4*1.5) -> 264631134745 | U4: =SUM(H4*W4) -> 319321569259 | V4: =SUM(H4*W4*1.5) -> 478982353888 | W4: 0.0428
A5: Areoix Lie | B5: =SUM(J5*K5) -> 5.7908744e+08 | C5: are-TOOR-lay | D5: /ɑːrˈtʊər.leɪ/ | E5: Acrola | F5: =SUM(G5*B5) -> 4595932041317 | G5: 7936.5079 | H5: 1.1173667e+13 | I5: =sum(H5/B5) -> 19295.303 | J5: 98.918 | K5: 5854217 | L5: =SUM(K5*0.386102) -> 2260324.9 | M5: 0.712 | N5: 5.23 | O5: 88 | P5: .lie | Q5: Vurahi | R5: Arten | S5: =SUM(F5*W5) -> 122711385503 | T5: =SUM(F5*W5*1.5) -> 184067078255 | U5: =SUM(H5*W5) -> 298336919178 | V5: =SUM(H5*W5*1.5) -> 447505378767 | W5: 0.0267
A6: Estijan | B6: =SUM(J6*K6) -> 2.6084482e+08 | C6: ESS-tee-jahn | D6: /ˈɛs.ti.dʒɑːn/ | E6: Ayuma | F6: =SUM(G6*B6) -> 2805116867175 | G6: 10753.968 | H6: 5.0577732e+12 | I6: =sum(H6/B6) -> 19389.97 | J6: 35.873 | K6: 7271341 | L6: =SUM(K6*0.386102) -> 2807479.3 | M6: 0.825 | N6: 6.21 | O6: 30 | P6: .est | Q6: Shabiran | R6: Estijan | S6: =SUM(F6*W6) -> 93690903364 | T6: =SUM(F6*W6*1.5) -> 140536355045 | U6: =SUM(H6*W6) -> 168929625425 | V6: =SUM(H6*W6*1.5) -> 253394438137 | W6: 0.0334
A7: Etirha | B7: =SUM(J7*K7) -> 74667447 | C7: EH-teer-hah | D7: /ˈɛ.tɪər.hɑː/ | E7: Atirha | F7: =SUM(G7*B7) -> 2642990568619 | G7: 35396.825 | H7: 2.1910392e+12 | I7: =sum(H7/B7) -> 29343.968 | J7: 40.0399 | K7: 1864826 | L7: =SUM(K7*0.386102) -> 720013.05 | M7: 0.969 | N7: 9.04 | O7: 22 | P7: .eti | Q7: Albiran | R7: Etirhan | S7: =SUM(F7*W7) -> 57617194396 | T7: =SUM(F7*W7*1.5) -> 86425791594 | U7: =SUM(H7*W7) -> 47764654154 | V7: =SUM(H7*W7*1.5) -> 71646981231 | W7: 0.0218
A8: Verusa | B8: =SUM(J8*K8) -> 69480631 | C8: VEH-roo-sah | D8: /ˈvɛr.uː.sɑː/ | E8: Ayuma | F8: =SUM(G8*B8) -> 1549528349095 | G8: 22301.587 | H8: 1.8682335e+12 | I8: =sum(H8/B8) -> 26888.552 | J8: 95.1 | K8: 730606 | L8: =SUM(K8*0.386102) -> 282088.44 | M8: 0.974 | N8: 9.59 | O8: 12 | P8: .ver | Q8: Huifarn | R8: Verusan | S8: =SUM(F8*W8) -> 54233492218 | T8: =SUM(F8*W8*1.5) -> 81350238328 | U8: =SUM(H8*W8) -> 65388173629 | V8: =SUM(H8*W8*1.5) -> 98082260443 | W8: 0.035
A9: Emara | B9: =SUM(J9*K9) -> 90861040 | C9: eh-MAH-rah | D9: /ɛˈmɑː.rə/ | E9: Ayuma | F9: =SUM(G9*B9) -> 2109274137239 | G9: 23214.286 | H9: 2.6936451e+12 | I9: =sum(H9/B9) -> 29645.766 | J9: 211.903 | K9: 428786 | L9: =SUM(K9*0.386102) -> 165555.13 | M9: 0.945 | N9: 7.64 | O9: 1 | P9: .ema | Q9: Rivostan | R9: Emaran | S9: =SUM(F9*W9) -> 53153708258 | T9: =SUM(F9*W9*1.5) -> 79730562388 | U9: =SUM(H9*W9) -> 67879856589 | V9: =SUM(H9*W9*1.5) -> 101819784883 | W9: 0.0252
A10: Sunsokua | B10: =SUM(J10*K10) -> 79558877 | C10: sun-SOH-koo-ah | D10: /sʌnˈsoʊ.ku.ə/ | E10: Mahea | F10: =SUM(G10*B10) -> 1000800162006 | G10: 12579.365 | H10: 1401120226808 | I10: =sum(H10/B10) -> 17611.111 | J10: 107.8092 | K10: 737960 | L10: =SUM(K10*0.386102) -> 284927.83 | M10: 0.918 | N10: 8.92 | O10: 744 | P10: .sun | Q10: Mikalu | R10: Sunsokuan | S10: =SUM(F10*W10) -> 45936727436 | T10: =SUM(F10*W10*1.5) -> 68905091154 | U10: =SUM(H10*W10) -> 64311418410 | V10: =SUM(H10*W10*1.5) -> 96467127616 | W10: 0.0459
A11: Ztesh | B11: =SUM(J11*K11) -> 4.2514143e+08 | C11: ZUH-tesh | D11: /ˈzʌ.tɛʃ/ | E11: Quia | F11: =SUM(G11*B11) -> 1449192426574 | G11: 3408.7302 | H11: 4.21715e+12 | I11: =sum(H11/B11) -> 9919.4048 | J11: 252.715 | K11: 1682296 | L11: =SUM(K11*0.386102) -> 649537.85 | M11: 0.66 | N11: 6.24 | O11: 71 | P11: .zte | Q11: Nakos | R11: Zteshi | S11: =SUM(F11*W11) -> 42606257341 | T11: =SUM(F11*W11*1.5) -> 63909386012 | U11: =SUM(H11*W11) -> 123984208863 | V11: =SUM(H11*W11*1.5) -> 185976313295 | W11: 0.0294
A12: Lycroa | B12: =SUM(J12*K12) -> 81313729 | C12: LIE-kroh-uh | D12: /ˈlaɪ.kroʊ.ə/ | E12: Ayuma | F12: =SUM(G12*B12) -> 1677902350965 | G12: 20634.921 | H12: 2.1289136e+12 | I12: =sum(H12/B12) -> 26181.477 | J12: 164.407 | K12: 494588 | L12: =SUM(K12*0.386102) -> 190961.42 | M12: 0.939 | N12: 8.46 | O12: 19 | P12: .lyc | Q12: Jungui | R12: Lycroan | S12: =SUM(F12*W12) -> 40773027128 | T12: =SUM(F12*W12*1.5) -> 61159540693 | U12: =SUM(H12*W12) -> 51732599570 | V12: =SUM(H12*W12*1.5) -> 77598899355 | W12: 0.0243
A13: Seytinemas | B13: =SUM(J13*K13) -> 71957346 | C13: SAY-tee-neh-mahs | D13: /ˈseɪ.ti.nɛ.mɑːs/ | E13: Mahea | F13: =SUM(G13*B13) -> 790959715767 | G13: 10992.063 | H13: 1.4790947e+12 | I13: =sum(H13/B13) -> 20555.159 | J13: 82.0123 | K13: 877397 | L13: =SUM(K13*0.386102) -> 338764.74 | M13: 0.832 | N13: 6.08 | O13: 921 | P13: .sey | Q13: Vulna | R13: Seytinemese | S13: =SUM(F13*W13) -> 37254202613 | T13: =SUM(F13*W13*1.5) -> 55881303919 | U13: =SUM(H13*W13) -> 69665358886 | V13: =SUM(H13*W13*1.5) -> 104498038328 | W13: 0.0471
... A169: Tonder | B169: =SUM(J169*K169) -> 143924.55 | C169: TON-der | D169: /ˈtɒn.dər/ | E169: Ayuma | F169: =SUM(G169*B169) -> 154204875 | G169: 1071.4286 | H169: 4.5644643e+08 | I169: =sum(H169/B169) -> 3171.4286 | J169: 6.545 | K169: 21990 | L169: =SUM(K169*0.386102) -> 8490.383 | M169: 0.662 | N169: 4.44 | O169: 185 | P169: .ton | Q169: Tonder | R169: Tonderian | S169: =SUM(F169*W169) -> 3084097.5 | T169: =SUM(F169*W169*1.5) -> 4626146.2 | U169: =SUM(H169*W169) -> 9128928.6 | V169: =SUM(H169*W169*1.5) -> 13693393 | W169: 0.02
A170: Letan | B170: 76045.2 | C170: LEH-tahn | D170: /ˈlɛ.tɑːn/ | E170: Quia | F170: 1.2342257e+08 | G170: 1623.0159 | H170: 3.2830403e+08 | I170: =sum(H170/B170) -> 4317.2222 | J170: 46.2 | K170: 1646 | L170: 635.52389 | M170: 0.72 | N170: 2.47 | O170: 780 | P170: .let | Q170: Actilica | R170: Letan | S170: 0 | T170: =SUM(F170*W170*1.5) -> 3702677 | U170: =SUM(H170*W170) -> 6566080.5 | V170: =SUM(H170*W170*1.5) -> 9849120.8 | W170: 0.02
A171: Tvecoca | B171: =SUM(J171*K171) -> 5165.16 | C171: tveh-KOH-kah | D171: /ˌtvɛˈkoʊ.kɑː/ | E171: New Ayre | F171: =SUM(G171*B171) -> 48167167 | G171: 9325.3968 | H171: 94407647 | I171: =sum(H171/B171) -> 18277.778 | J171: 40.04 | K171: 129 | L171: =SUM(K171*0.386102) -> 49.807158 | M171: 0.822 | N171: 5.15 | O171: 616 | P171: .tve | Q171: Lurvani | R171: Tvecocan | S171: =SUM(F171*W171) -> 963343.33 | T171: =SUM(F171*W171*1.5) -> 1445015 | U171: =SUM(H171*W171) -> 1888152.9 | V171: =SUM(H171*W171*1.5) -> 2832229.4 | W171: 0.02
A172: Trevilla | B172: =SUM(J172*K172) -> 10360.45 | C172: treh-VILL-ah | D172: /ˌtrɛˈvɪl.ɑː/ | E172: Acrola | F172: =SUM(G172*B172) -> 36590478 | G172: 3531.746 | H172: 90744386 | I172: =sum(H172/B172) -> 8758.7302 | J172: 19.01 | K172: 545 | L172: =SUM(K172*0.386102) -> 210.42559 | M172: 0.747 | N172: 6.12 | O172: 345 | P172: .tre | Q172: City Tirnsch | R172: Trevillian | S172: =SUM(F172*W172) -> 731809.56 | T172: =SUM(F172*W172*1.5) -> 1097714.3 | U172: =SUM(H172*W172) -> 1814887.7 | V172: =SUM(H172*W172*1.5) -> 2722331.6 | W172: 0.02
A173: Cruthi Anoso | B173: =SUM(J173*K173) -> 3983.807 | C173: KROO-thee AH-noh-soh | D173: /ˈkruː.θi ˈɑː.noʊ.soʊ/ | E173: Mahea | F173: =SUM(G173*B173) -> 7524968.8 | G173: 1888.8889 | H173: 22273908 | I173: =sum(H173/B173) -> 5591.1111 | J173: 17.3209 | K173: 230 | L173: =SUM(K173*0.386102) -> 88.80346 | M173: 0.659 | N173: 7.45 | O173: 955 | P173: .cru | Q173: Lunarev | R173: Cruthite | S173: =SUM(F173*W173) -> 150499.38 | T173: =SUM(F173*W173*1.5) -> 225749.06 | U173: =SUM(H173*W173) -> 445478.15 | V173: =SUM(H173*W173*1.5) -> 668217.23 | W173: 0.02
A174: Totals | B174: =SUM(ALL[Population]) -> 6750557645 | E174: N/a | F174: =SUM(ALL[GDP (Nominal)]) -> 62761418039984 | G174: =sum(ALL[[#TOTALS],[GDP (Nominal)]]/ALL[[#TOTALS],[Population]]) -> 9297.2198 | H174: =SUM(ALL[GDP (PPP)]) -> 109171110759386 | I174: =sum(ALL[[#TOTALS],[GDP (PPP)]]/ALL[[#TOTALS],[Population]]) -> 16172.162 | J174: =sum(ALL[[#TOTALS],[Population]]/ALL[[#TOTALS],[Area (Km)]]) -> 53.724624 | K174: =SUM(ALL[Area (Km)]) -> 125651092 | L174: =SUM(ALL[Area (Mi)]) -> 48514138 | M174: N/a | N174: N/a | O174: N/a | P174: N/a | Q174: Suraspa | S174: =SUM(ALL!$S$2:$S$173) -> 1781251406476 | T174: =SUM(ALL!$T$2:$T$173) -> 2671880812391 | U174: =SUM(ALL!$U$2:$U$173) -> 3054715591231 | V174: =SUM(ALL!$V$2:$V$173) -> 4582073386847 | W174: =SUM(W175/172) -> 0.022175
W175: =SUM(ALL!$W$2:$W$173) -> 3.8141

Sheet Wiki maker
A1: Name | B1: Area (Km) | C1: Population | D1: Density | E1: GDP (PPP) | F1: GDP (Nominal) | G1: Per (NOM) | H1: Num | I1: Continent | J1: Geoscheme
A2: Finae | B2: 440878 | C2: 31745420 | D2: 72.005 | E2: 6.2606352e+11 | F2: 3.4264898e+11 | G2: 10793.651 | H2: 1 | I2: Quia | J2: East Quia | K2: =CONCATENATE(A2",,"%",,") -> #ERROR!
A3: Hyelen | B3: 154449 | C3: 1724423.1 | D3: 11.165 | E3: 11381192361 | F3: 4.2152564e+09 | G3: 2444.4444 | H3: 1 | I3: Quia | J3: East Quia | K3: =CONCATENATE("| ",B3," || ",C3," || ",D3," || ",E3," || ",F3," || ",G3," ") -> | 154449 || 1724423.085 || 11.165 || 11381192361 || 4215256430. || 2444.44444444444 | M3: |-
A4: Myla | B4: 431272 | C4: 42672208 | D4: 98.945 | E4: 7.2414117e+11 | F4: 3.1326819e+11 | G4: 7341.2698 | H4: 1 | I4: Quia | J4: East Quia | K4: =CONCATENATE("| ",B4," || ",C4," || ",D4," || ",E4," || ",F4," || ",G4," ") -> | 431272 || 42672208.04 || 98.945 || 724141172136.111 || 313268193944.444 || 7341.26984126984 | M4: =#REF! -> #REF!
A5: Nheyes Si | B5: 266831 | C5: 12224862 | D5: 45.815 | E5: 1.271279e+11 | F5: 4.4921518e+10 | G5: 3674.6032 | H5: 1 | I5: Quia | J5: East Quia | K5: =CONCATENATE("| ",B5," || ",C5," || ",D5," || ",E5," || ",F5," || ",G5," ") -> | 266831 || 12224862.265 || 45.815 || 127127895057.197 || 44921517688.0556 || 3674.60317460317 | M5: |-
A6: Onphello | B6: 255572 | C6: 10233103 | D6: 40.04 | E6: 1.004306e+11 | F6: 3.7196517e+10 | G6: 3634.9206 | H6: 1 | I6: Quia | J6: East Quia | K6: =CONCATENATE("| ",B6," || ",C6," || ",D6," || ",E6," || ",F6," ") -> | 255572 || 10233102.88 || 40.04 || 100430595408. || 37196516817.7778 | M6: =K2 -> #ERROR!
A7: Volver | B7: 1542246 | C7: 17219177 | D7: 11.165 | E7: 2.2663138e+11 | F7: 127093922450 | G7: 7380.9524 | H7: 1 | I7: Quia | J7: East Quia | K7: =CONCATENATE("| ",B7," || ",C7," || ",D7," || ",E7," || ",F7," ") -> | 1542246 || 17219176.59 || 11.165 || 226631380696.5 || 127093922450 | M7: |-
A8: Zhanshe | B8: 5310404 | C8: 7354909.5 | D8: 1.385 | E8: 3.7145212e+09 | F8: 2.5975673e+09 | G8: 353.1746 | H8: 1 | I8: Quia | J8: East Quia | K8: =CONCATENATE("| ",B8," || ",C8," || ",D8," || ",E8," || ",F8," ") -> | 5310404 || 7354909.54 || 1.385 || 3714521179.18968 || 2597567258.1746 | M8: =K4 -> | 431272 || 42672208.04 || 98.945 || 724141172136.111 || 313268193944.444 || 7341.26984126984
I9: New Ayre | J9: North New Ayre | K9: =CONCATENATE("| ",B9," || ",C9," || ",D9," || ",E9," || ",F9," ") -> | || || || || | M9: |-
I10: New Ayre | J10: North New Ayre | K10: =CONCATENATE("| ",B10," || ",C10," || ",D10," || ",E10," || ",F10," ") -> | || || || || | M10: =K5 -> | 266831 || 12224862.265 || 45.815 || 127127895057.197 || 44921517688.0556 || 3674.60317460317
I11: New Ayre | J11: North New Ayre | K11: =CONCATENATE("| ",B11," || ",C11," || ",D11," || ",E11," || ",F11," ") -> | || || || || | M11: |-
I12: New Ayre | J12: North New Ayre | K12: =CONCATENATE("| ",B12," || ",C12," || ",D12," || ",E12," || ",F12," ") -> | || || || || | M12: =K6 -> | 255572 || 10233102.88 || 40.04 || 100430595408. || 37196516817.7778
I13: New Ayre | J13: North New Ayre | K13: =CONCATENATE("| ",B13," || ",C13," || ",D13," || ",E13," || ",F13," ") -> | || || || || | M13: |-
I14: New Ayre | J14: North New Ayre | K14: =CONCATENATE("| ",B14," || ",C14," || ",D14," || ",E14," || ",F14," ") -> | || || || || | M14: =K7 -> | 1542246 || 17219176.59 || 11.165 || 226631380696.5 || 127093922450
K15: =CONCATENATE("| ",B15," || ",C15," || ",D15," || ",E15," || ",F15," ") -> | || || || || | M15: |-
K16: =CONCATENATE("| ",B16," || ",C16," || ",D16," || ",E16," || ",F16," ") -> | || || || || | M16: =K8 -> | 5310404 || 7354909.54 || 1.385 || 3714521179.18968 || 2597567258.1746
K17: =CONCATENATE("| ",B17," || ",C17," || ",D17," || ",E17," || ",F17," ") -> | || || || || | M17: |-
K18: =CONCATENATE("| ",B18," || ",C18," || ",D18," || ",E18," || ",F18," ") -> | || || || || | M18: =K9 -> | || || || ||
K19: =CONCATENATE("| ",B19," || ",C19," || ",D19," || ",E19," || ",F19," ") -> | || || || || | M19: |-
K20: =CONCATENATE("| ",B20," || ",C20," || ",D20," || ",E20," || ",F20," ") -> | || || || || | M20: =K10 -> | || || || ||
K21: =CONCATENATE("| ",B21," || ",C21," || ",D21," || ",E21," || ",F21," ") -> | || || || || | M21: |-
K22: =CONCATENATE("| align=left | {{flag|",A22,"}} || ",B22," || ",C22," || ",D22," || ",E22," || ",F22," ") -> | align=left | {{flag|}} || || || || || | M22: =K11 -> | || || || ||
K23: =CONCATENATE("| align=left | {{flag|",A23,"}} || ",B23," || ",C23," || ",D23," || ",E23," || ",F23," ") -> | align=left | {{flag|}} || || || || || | M23: |-
A24: South Ayuma | B24: =SUM(B2:B23) -> 8401652 | C24: =SUM(C2:C23) -> 1.231741e+08 | D24: =SUM(C24/B24) -> 14.6607 | E24: =SUM(E2:E23) -> 1819490272887 | F24: =SUM(F2:F23) -> 871941956576 | G24: =SUM(F24/C24) -> 7078.939 | H24: =SUM(H2:H23) -> 7 | K24: =CONCATENATE("| align=left | {{flag|",A24,"}} || ",B24," || ",C24," || ",D24," || ",E24," || ",F24," ") -> | align=left | {{flag|South Ayuma}} || 8401652 || 123174102.79 || 14.6607003943986 || 1819490272887.01 || 871941956575.754 | M24: =K12 -> | || || || ||
A25: Name | B25: Area (Km) | C25: Population | D25: Density | E25: GDP (PPP) | F25: GDP (Nominal) | G25: Per (NOM) | H25: Num | K25: =CONCATENATE("| align=left | {{flag|",A25,"}} || ",B25," || ",C25," || ",D25," || ",E25," || ",F25," ") -> | align=left | {{flag|Name}} || Area (Km) || Population || Density || GDP (PPP) || GDP (Nominal) | M25: |-
K26: =CONCATENATE("| align=left | {{flag|",A26,"}} || ",B26," || ",C26," || ",D26," || ",E26," || ",F26," ") -> | align=left | {{flag|}} || || || || || | M26: =K13 -> | || || || ||
K27: =CONCATENATE("| align=left | {{flag|",A27,"}} || ",B27," || ",C27," || ",D27," || ",E27," || ",F27," ") -> | align=left | {{flag|}} || || || || || | M27: |-
K28: =CONCATENATE("| align=left | {{flag|",A28,"}} || ",B28," || ",C28," || ",D28," || ",E28," || ",F28," ") -> | align=left | {{flag|}} || || || || || | M28: =K14 -> | || || || ||
K29: =CONCATENATE("| align=left | {{flag|",A29,"}} || ",B29," || ",C29," || ",D29," || ",E29," || ",F29," ") -> | align=left | {{flag|}} || || || || || | M29: |-
K30: =CONCATENATE("| align=left | {{flag|",A30,"}} || ",B30," || ",C30," || ",D30," || ",E30," || ",F30," ") -> | align=left | {{flag|}} || || || || || | M30: =K15 -> | || || || ||
K31: =CONCATENATE("| align=left | {{flag|",A31,"}} || ",B31," || ",C31," || ",D31," || ",E31," || ",F31," ") -> | align=left | {{flag|}} || || || || || | M31: |-
K32: =CONCATENATE("| align=left | {{flag|",A32,"}} || ",B32," || ",C32," || ",D32," || ",E32," || ",F32," ") -> | align=left | {{flag|}} || || || || || | M32: =K16 -> | || || || ||
K33: =CONCATENATE("| align=left | {{flag|",A33,"}} || ",B33," || ",C33," || ",D33," || ",E33," || ",F33," ") -> | align=left | {{flag|}} || || || || || | M33: |-
K34: =CONCATENATE("| align=left | {{flag|",A34,"}} || ",B34," || ",C34," || ",D34," || ",E34," || ",F34," ") -> | align=left | {{flag|}} || || || || || | M34: =K17 -> | || || || ||
K35: =CONCATENATE("| align=left | {{flag|",A35,"}} || ",B35," || ",C35," || ",D35," || ",E35," || ",F35," ") -> | align=left | {{flag|}} || || || || || | M35: |-
K36: =CONCATENATE("| align=left | {{flag|",A36,"}} || ",B36," || ",C36," || ",D36," || ",E36," || ",F36," ") -> | align=left | {{flag|}} || || || || || | M36: =K18 -> | || || || ||
K37: =CONCATENATE("| align=left | {{flag|",A37,"}} || ",B37," || ",C37," || ",D37," || ",E37," || ",F37," ") -> | align=left | {{flag|}} || || || || || | M37: |-
K38: =CONCATENATE("| align=left | {{flag|",A38,"}} || ",B38," || ",C38," || ",D38," || ",E38," || ",F38," ") -> | align=left | {{flag|}} || || || || || | M38: =K19 -> | || || || ||
K39: =CONCATENATE("| align=left | {{flag|",A39,"}} || ",B39," || ",C39," || ",D39," || ",E39," || ",F39," ") -> | align=left | {{flag|}} || || || || || | M39: |-
K40: =CONCATENATE("| align=left | {{flag|",A40,"}} || ",B40," || ",C40," || ",D40," || ",E40," || ",F40," ") -> | align=left | {{flag|}} || || || || || | M40: =K20 -> | || || || ||
...

Sheet Geoscheme
A1: Continent | B1: Geoscheme | C1: Name | D1: Area (Km) | E1: Population | F1: Density | G1: GDP (PPP) | H1: GDP (Nominal) | I1: Per (NOM) | J1: Column 1
A2: Acrola | B2: Middle Acrola | C2: Eldavpir | D2: 574577 | E2: 29421790 | F2: 51.206 | G2: 1.3081255e+11 | H2: 3.5259447e+10 | I2: 1198.4127 | J2: 1
A3: Acrola | B3: Middle Acrola | C3: Iquir | D3: 489302 | E3: 36356117 | F3: 74.302 | G3: 1.4017303e+11 | H3: 4.0395686e+10 | I3: 1111.1111 | J3: 1
A4: Acrola | B4: Middle Acrola | C4: Viussi | D4: 388247 | E4: 17339111 | F4: 44.66 | G4: 7.9069787e+10 | H4: 2.3187621e+10 | I4: 1337.3016 | J4: 1
A5: Acrola | B5: Middle Acrola | C5: Umendel | D5: 338878 | E5: 7437016.6 | F5: 21.946 | G5: 3.2227957e+10 | H5: 7.8796961e+09 | I5: 1059.5238 | J5: 1
A6: Acrola | B6: Middle Acrola | C6: Reerica | D6: 264853 | E6: 8871251.2 | F6: 33.495 | G6: 106948499432 | H6: 67590485600 | I6: 7619.0476 | J6: 1
A7: Acrola | B7: Middle Acrola | C7: Saa | D7: 236495 | E7: 2549416.1 | F7: 10.78 | G7: 1.6073462e+10 | H7: 4.8560307e+09 | I7: 1904.7619 | J7: 1
A8: Acrola | B8: Middle Acrola | C8: Sattle | D8: 232273 | E8: 9388939.2 | F8: 40.422 | G8: 1.8214542e+10 | H8: 6259292804 | I8: 666.66667 | J8: 1
A9: Acrola | B9: North Acrola | C9: Areoix Lie | D9: 5854217 | E9: 5.7908744e+08 | F9: 98.918 | G9: 1.1173667e+13 | H9: 4.595932e+12 | I9: 7936.5079 | J9: 1
A10: Acrola | B10: North Acrola | C10: Jau | D10: 2059631 | E10: 22993720 | F10: 11.164 | G10: 3.3222276e+10 | H10: 1.0036941e+10 | I10: 436.50794 | J10: 1
A11: Acrola | B11: North Acrola | C11: Terressin | D11: 1112428 | E11: 74091042 | F11: 66.603 | G11: 759433181361 | H11: 3.6163485e+11 | I11: 4880.9524 | J11: 1
A12: Acrola | B12: North Acrola | C12: Acetoa | D12: 388005 | E12: 11203256 | F12: 28.874 | G12: 175393033450 | H12: 93360469750 | I12: 8333.3333 | J12: 1
A13: Acrola | B13: North Acrola | C13: Feio Lie | D13: 229074 | E13: 7849449.7 | F13: 34.266 | G13: 112508778804 | H13: 43608053800 | I13: 5555.5556 | J13: 1
... A173: Quia | B173: West Quia | C173: Ahokini | D173: 168631 | E173: 20712946 | F173: 122.83 | G173: 6.3361887e+11 | H173: 4.800143e+11 | I173: 23174.603 | J173: 1
E186: Population | F186: Density
E187: 11203256 | F187: 28.874
E188: 14469041 | F188: 109.727
E189: 1405386.8 | F189: 55.0506
E190: 20712946 | F190: 122.83
E191: 2236563.4 | F191: 6.1605
E192: 3146472.6 | F192: 1.54
E193: 21768597 | F193: 43.505
E194: 376608.95 | F194: 10.3938
E195: 6585930 | F195: 11.9346
E196: 5.7908744e+08 | F196: 98.918
E197: 62265521 | F197: 147.47
E198: 44277194 | F198: 83.5496
... E358: 4.2514143e+08 | F358: 252.715
E359: 6.7505576e+09 | F359: =sum(ALL[[#TOTALS],[Population]]/ALL[[#TOTALS],[Area (Km)]]) -> 53.724624
E371: Population | F371: Density
E372: 11203256 | F372: 28.874
E373: 14469041 | F373: 109.727
E374: 1405386.8 | F374: 55.0506
E375: 20712946 | F375: 122.83
E376: 2236563.4 | F376: 6.1605
E377: 3146472.6 | F377: 1.54
E378: 21768597 | F378: 43.505
E379: 376608.95 | F379: 10.3938
E380: 6585930 | F380: 11.9346
E381: 5.7908744e+08 | F381: 98.918
...

Sheet Great Importance
A1: Demonym | B1: Name | C1: Capital | D1: Population | E1: GDP (Nominal) | F1: Per (NOM) | G1: Allineces | H1: Alliance | I1: Economic | J1: Military | K1: Strategic Interests | L1: Current Status | M1: Primary Threats
A2: Raledrian | B2: Raledria | C2: Tirna | D2: 301M | E2: W8,5T | F2: M28,492 | G2: ADT, BDT, DAC, RSDA | K2: Maintaining technological supremacy, countering Dahe in Eanif-Vish, energy independence, DAC leadership | L2: Post-election transition. Focus on trade policy, border security, and Rianan alliances. Defense spending at 3.4% GDP. | M2: Areoix Lie, Pelugrotoa
A3: Dahen | B3: Dahe | C3: Fekunza | D3: 890M | E3: M9,5T | F3: M10,755 | G3: BDT, DAC, RRO, SHISA | K3: Naval expansion in Adrad Sea, Massiran free trade zone, technological self-reliance, industrial competitiveness | L3: Economic slowdown, demographic challenges. Energy diversification. Tensions with Pelugrotoa over Seytiemas and tech. | M3: Areoix Lie , Ocaun, Pelugrotoa
A4: Pelugrotoan | B4: Pelugrotoa | C4: Thavrin | D4: 347M | E4: M4,1T | F4: M11,861 | G4: APA, MPU, NMCC | K4: Military expansion across Mahea, Mahean Petroleum Union, Focus on asymmetric capabilities and energy leverage. | L4: New administration. Economic growth. Tensions with Sunsokua over Riala Island and Oil drilling rights. | M4: Dahe, Ocaun, Sunsokua
A5: Arten | B5: Areoix Lie | C5: Vurahi | D5: 579M | E5: M4,5T | F5: M7,937 | G5: AANS, APA | K5: Countering Estijan, Pelugrotoan partnership, energy security, counter-terrorism | L5: AANS active. Rapid economic growth. Defense modernization. Resource exports critical. | M5: Estijan, Raledria
A6: Estijan | B6: Estijan | C6: Shabiran | D6: 260M | E6: M2,8T | F6: M10,754 | G6: AFTZ | K6: Ayuman dominance, defense modernization, maintaining influence in former Huan states, countering Arten and Raledria expansion | L6: Labour government focuses on economic stability. Energy diversification from Areoix Lie. Border tensions with Fermori persist | M6: Areoix Lie, Raledria
A7: Etirhan | B7: Etirha | C7: Albiran | D7: 74M | E7: M2,6T | F7: M35,397 | G7: DAC | K7: Moaneill sovereignty, energy exports, defense spending, supporting Pelan, Raledria relations | L7: New government focuses on defense modernization. Ayren security priority. Economic challenges | M7: Pelan, Migration
A8: Verusan | B8: Verusa | C8: Huifarn | D8: 69M | E8: M1,5T | F8: M22,302 | G8: DAC, RSDA | K8: Energy transition, defense spending increase, industrial competitiveness, trade agreements | L8: Post-election coalition formation. Defense spending target 4% GDP. Energy diversification from Pelugrotoa. | M8: Emara, Estijan
A9: Emaran | B9: Emara | C9: Rivostan | D9: 90M | E9: M2.1T | F9: M23,214 | G9: DAC | K9: Global Emara, Kera-Ubrana pivot, defense modernization, Border tensions with Etretes persist. | L9: Defense spending increase. Strong support for Ukraine. Tensions in Koaissan region. Nuclear modernization. | M9: Raledria, Verusa
A10: Sunsokuan | B10: Sunsokua | C10: Mikalu | D10: 79M | E10: M1.0T | F10: M12,579 | G10: SHDA, SHISA | K10: Energy market control, economic diversification, regional influence, countering Pelugrotoa | L10: Economic diversification efforts. Normalization talks with Pelugrotoa. countering Ocaun. | M10: Pelugrotoa, Ocaun
A11: Zteshi | B11: Ztesh | C11: Nakos | D11: 425M | E11: M1.4T | F11: M3,408 | G11: QU | K11: Quian leadership, digital infrastructure, countering Raledrian infuence, energy security, space capabilities | L11: Rapid economic growth. Strengthening ties with Dahe and Pelugrotoa. Border tensions with Wundry persist. | M11: United Mihili
A12: Lycroan | B12: Lycroa | C12: Jungui | D12: 81M | E12: M1.6T | F12: M20,635 | G12: DAC+ | K12: National integration, migration control, energy security, defense modernization | L12: Right-wing government. Support for Raledria. Energy diversification from Sunsokua. Economic challenges. | M12: Emara, Estijan
A13: Seytinemese | B13: Seytinemas | C13: Vulna | D13: 71M | E13: M790B | F13: M10,992 | G13: DAC+, SHISA | K13: Maritime security, trade hub, balancing Dahen-Pelugrotoan, technology | L13: New OSI administration. Pelugrotoan tensions. Strong Dahen support. Semiconductor hub. | M13: Dual Cenryia, Pelugrotoa
... A24: Tavalan | B24: Taval | C24: Suraspa | D24: 44M | E24: M473B | F24: M10,635 | G24: DAC+, RSDA | K24: RSDA leadership, maritime security, economic growth, balancing Raledrian-Emaran | L24: Economic crisis. Ucrua border tensions. Raledrian support. Energy diversification. | M24: Dahe, Emara
A25: Ocunese | B25: Ocaun | C25: Kejira | D25: 88M | E25: M43B | F25: M488 | K25: Nuclear program, regional proxy influence, countering Pelugrotoa, economic independence | L25: Civil war ongoing. Raledrian support critical. Reconstruction needs. | M25: Everyone
A26: Pelinese | B26: Pelines | C26: Dalyar | D26: 88M | E26: M225B | F26: M2,560 | G26: SACC | K26: Regional leadership, energy exports, counter-terrorism, economic diversification | L26: Largest south acrolan economy. Security challenges in north. Oil-dependent. Population growth. | M26: ACF, Economic
A27: Ashani | B27: Ahokini | C27: Ribash | D27: 20M | E27: M633B | F27: M30,590 | G27: QU | K27: Energy exports, regional influence, technology hub, normalization | L27: Economic diversification. Normalization with Ashain. Regional diplomacy. Energy wealth. | M27: United Mihili, Migration

Sheet Earth Comparsion
A1: Name | B1: Historical
A2: Dahe | B2: Done
A3: Pelugrotoa | B3: Done
A4: Areoix Lie | B4: N/a
A5: Raledria | B5: Done
A6: Estijan | B6: Done
A7: Ztesh | B7: Done
A8: Seytinemas | B8: Greece/Bulgaria
A9: Emara | B9: Done
A10: Verusa | B10: Done
A11: Sunsokua | B11: Korea
A12: Verste | B12: Arabia
... A45: Genaire | B45: Canada
A46: Selaja
A47: Darewa | B47: Poland
A48: Astye | B48: Argentina
A49: Ahokini | B49: Taiwan
A50: Yaxuto | B50: North Italy
A51: Merela Sta | B51: South Italy
A52: Otiiric | B52: Denmark
A53: Isnti | B53: Turkey
A54: Lydroa | B54: Belarus
A55: Chaenia | B55: Malaysia
A56: Sadain
A57: Haiza | B57: Greek colony
A58: Heiso | B58: Manchuria
A59: Hkuqo | B59: Greek colony
A60: Iareva | B60: Norway
A61: Volver | B61: Cambodia
A62: North Ayre | B62: Part of Indonesia
A63: Acrana | B63: Armenia
A64: Geaiya | B64: Canada
A65: Sivoso | B65: Turkey
A66: Maalle | B66: Bolivia
A67: Deschon | B67: Congo
A68: Isari | B68: Peru
... A70: Fermori | B70: Estonia
A71: Acetoa
A72: Ucrua | B72: South Africa
A73: Umarcia | B73: Ecuador
...

Sheet Acrola
A1: Continent | B1: Pronunciation | C1: IPA Use (https://ipa-reader.com/) | D1: Name | E1: Population | F1: GDP (Nominal) | G1: Per (NOM) | H1: GDP (PPP) | I1: Per (PPP) | J1: Density | K1: Area (Km) | L1: Area (Mi) | M1: KTDI | N1: GDI | O1: Phone | P1: Domain | Q1: Capital | R1: Demonym | S1: Military | T1: Per GDP
A2: Acrola | B2: sun-SOH-koo-ah | C2: /sʌnˈsoʊ.ku.ə/ | D2: Areoix Lie | E2: =SUM(J2*K2) -> 5.7908744e+08 | F2: =SUM(G2*E2) -> 4595932041317 | G2: 7936.5079 | H2: 1.1173667e+13 | I2: =sum(H2/E2) -> 19295.303 | J2: 98.918 | K2: 5854217 | L2: =SUM(K2*0.386102) -> 2260324.9 | M2: 0.712 | N2: 5.23 | O2: 88 | P2: .lie | Q2: Vurahi | R2: Arten | S2: =SUM(F2*T2) -> 122711385503 | T2: 0.0267
A3: Acrola | B3: REE-jahn boo | C3: /ˈriː.dʒɑːn buː/ | D3: Pelines | E3: =SUM(J3*K3) -> 88057485 | F3: =SUM(G3*E3) -> 225385229080 | G3: 2559.5238 | H3: 7.3250199e+11 | I3: =sum(H3/E3) -> 8318.4524 | J3: 118.194 | K3: 745025 | L3: =SUM(K3*0.386102) -> 287655.64 | M3: 0.637 | N3: 5.31 | O3: 940 | P3: .pli | Q3: Dalyar | R3: Pelinese | S3: =SUM(F3*T3) -> 4733089811 | T3: 0.021
A4: Acrola | B4: da-NO-see-ah | C4: /ˌdæ.noʊˈsiː.ə/ | D4: Terressin | E4: =SUM(J4*K4) -> 74091042 | F4: =SUM(G4*E4) -> 361634848267 | G4: 4880.9524 | H4: 759433181361 | I4: =sum(H4/E4) -> 10250 | J4: 66.603 | K4: 1112428 | L4: =SUM(K4*0.386102) -> 429510.68 | M4: 0.655 | N4: 7.61 | O4: 81 | P4: .ter | Q4: Velloro | R4: Terressin | S4: =SUM(F4*T4) -> 7232696965 | T4: 0.02
A5: Acrola | B5: SAH | C5: /sɑː/ | D5: Taniduna | E5: =SUM(J5*K5) -> 45062542 | F5: =SUM(G5*E5) -> 10550357120 | G5: 234.12698 | H5: 3.9774846e+10 | I5: =sum(H5/E5) -> 882.65873 | J5: 25.796 | K5: 1746881 | L5: =SUM(K5*0.386102) -> 674474.25 | M5: 0.505 | N5: 4.96 | O5: 950 | P5: .tan | Q5: Zolittique | R5: Tanidunan | S5: =SUM(F5*T5) -> 3.9247328e+08 | T5: 0.0372
A6: Acrola | B6: SEE-voh-soh | C6: /ˈsiː.voʊ.soʊ/ | D6: Iquir | E6: =SUM(J6*K6) -> 36356117 | F6: =SUM(G6*E6) -> 40395685782 | G6: 1111.1111 | H6: 1.4017303e+11 | I6: =sum(H6/E6) -> 3855.5556 | J6: 74.302 | K6: 489302 | L6: =SUM(K6*0.386102) -> 188920.48 | M6: 0.56 | N6: 2.09 | O6: 910 | P6: .iqu | Q6: Chavillar | R6: Iquirian | S6: =SUM(F6*T6) -> 0
A7: Acrola | B7: TAH-vahl | C7: /ˈtɑː.vɑːl/ | D7: Deschon | E7: =SUM(J7*K7) -> 30642963 | F7: =SUM(G7*E7) -> 55813968660 | G7: 1821.4286 | H7: 1.9479075e+11 | I7: =sum(H7/E7) -> 6356.7857 | J7: 40.038 | K7: 765347 | L7: =SUM(K7*0.386102) -> 295502.01 | M7: 0.553 | N7: 4.51 | O7: 942 | P7: .dsc | Q7: Obelinti | R7: Deschonian | S7: =SUM(F7*T7) -> 0
A8: Acrola | B8: OO-lah-rin | C8: /ˈɜːr.bɪ.kjuː/ | D8: Othya | E8: =SUM(J8*K8) -> 30421695 | F8: =SUM(G8*E8) -> 33077557425 | G8: 1087.3016 | H8: 1.2701782e+11 | I8: =sum(H8/E8) -> 4175.2381 | J8: 65.835 | K8: 462090 | L8: =SUM(K8*0.386102) -> 178413.87 | M8: 0.487 | N8: 2.68 | O8: 947 | P8: .oth | Q8: Harlitak | R8: Othyan | S8: =SUM(F8*T8) -> 0
A9: Acrola | B9: TER-ruh-sin | C9: /ˈtɛr.ə.sɪn/ | D9: Eldavpir | E9: =SUM(J9*K9) -> 29421790 | F9: =SUM(G9*E9) -> 35259446581 | G9: 1198.4127 | H9: 1.3081255e+11 | I9: =sum(H9/E9) -> 4446.1111 | J9: 51.206 | K9: 574577 | L9: =SUM(K9*0.386102) -> 221845.33 | M9: 0.512 | N9: 5.62 | O9: 932 | P9: .eda | Q9: Lunfrix | R9: Eldavpiri | S9: =SUM(F9*T9) -> 0
A10: Acrola | B10: yoo-NY-tid DEH-let | C10: /juːˈnaɪ.tɪd ˈdɛ.lɛt/ | D10: Candenat | E10: =SUM(J10*K10) -> 27332521 | F10: =SUM(G10*E10) -> 8243141133 | G10: 301.5873 | H10: 3.4291467e+10 | I10: =sum(H10/E10) -> 1254.6032 | J10: 46.2 | K10: 591613 | L10: =SUM(K10*0.386102) -> 228422.96 | M10: 0.427 | N10: 1.98 | O10: 949 | P10: .can | Q10: Pavrette | R10: Candenati | S10: =SUM(F10*T10) -> 0
A11: Acrola | B11: FER-moh-ree | C11: /ˈfɜːr.moʊ.ri/ | D11: Jau | E11: =SUM(J11*K11) -> 22993720 | F11: =SUM(G11*E11) -> 10036941481 | G11: 436.50794 | H11: 3.3222276e+10 | I11: =sum(H11/E11) -> 1444.8413 | J11: 11.164 | K11: 2059631 | L11: =SUM(K11*0.386102) -> 795227.65 | M11: 0.595 | N11: 6.57 | O11: 80 | P11: .jau | Q11: Muntai | R11: Jauan | S11: =SUM(F11*T11) -> 0
A12: Acrola | B12: ruk-MEH-poo-ee-ah | C12: /ˌrʌkˈmɛ.puː.i.ɑː/ | D12: Viussi | E12: =SUM(J12*K12) -> 17339111 | F12: =SUM(G12*E12) -> 23187620689 | G12: 1337.3016 | H12: 7.9069787e+10 | I12: =sum(H12/E12) -> 4560.1984 | J12: 44.66 | K12: 388247 | L12: =SUM(K12*0.386102) -> 149902.94 | M12: 0.572 | N12: 4.39 | O12: 946 | P12: .viu | Q12: Zambhori | R12: Viussian | S12: =SUM(F12*T12) -> 0
A13: Acrola | B13: LAH-seltsh | C13: /ˈlɑː.sɛltʃ/ | D13: Jathua | E13: =SUM(J13*K13) -> 13153004 | F13: =SUM(G13*E13) -> 11274003840 | G13: 857.14286 | H13: 4.3066695e+10 | I13: =sum(H13/E13) -> 3274.2857 | J13: 12.32 | K13: 1067614 | L13: =SUM(K13*0.386102) -> 412207.9 | M13: 0.492 | N13: 1.76 | O13: 941 | P13: .jat | Q13: Nyvek | R13: Jathuan | S13: =SUM(F13*T13) -> 0
A14: Acrola | B14: ah-SEH-toh-ah | C14: /ɑːˈsɛ.toʊ.ə/ | D14: Jshain | E14: =SUM(J14*K14) -> 12584520 | F14: =SUM(G14*E14) -> 36555033240 | G14: 2904.7619 | H14: 1.0125744e+11 | I14: =sum(H14/E14) -> 8046.1905 | J14: 83.16 | K14: 151329 | L14: =SUM(K14*0.386102) -> 58428.43 | M14: 0.691 | N14: 4.21 | O14: 951 | P14: .jsh | Q14: Savyan | R14: Jshainian | S14: =SUM(F14*T14) -> 0
A15: Acrola | B15: dah-HAY | C15: /dɑːˈheɪ/ | D15: Acetoa | E15: =SUM(J15*K15) -> 11203256 | F15: =SUM(G15*E15) -> 93360469750 | G15: 8333.3333 | H15: 175393033450 | I15: =sum(H15/E15) -> 15655.54 | J15: 28.874 | K15: 388005 | L15: =SUM(K15*0.386102) -> 149809.51 | M15: 0.779 | N15: 8.74 | O15: 82 | P15: .ace | Q15: Yezhito | R15: Acetoan | S15: =SUM(F15*T15) -> 0
A16: Acrola | B16: RTEH-sah-nee-ah | C16: /ˌrtɛˈsɑː.ni.ə/ | D16: Sattle | E16: =SUM(J16*K16) -> 9388939.2 | F16: =SUM(G16*E16) -> 6259292804 | G16: 666.66667 | H16: 1.8214542e+10 | I16: =sum(H16/E16) -> 1940 | J16: 40.422 | K16: 232273 | L16: =SUM(K16*0.386102) -> 89681.07 | M16: 0.474 | N16: 1.35 | O16: 911 | P16: .sat | Q16: Espralit | R16: Sattlean | S16: =SUM(F16*T16) -> 0
A17: Acrola | B17: JAH-thoo-ah | C17: /ˈdʒɑː.θuː.ɑː/ | D17: Reerica | E17: =SUM(J17*K17) -> 8871251.2 | F17: =SUM(G17*E17) -> 67590485600 | G17: 7619.0476 | H17: 106948499432 | I17: =sum(H17/E17) -> 12055.627 | J17: 33.495 | K17: 264853 | L17: =SUM(K17*0.386102) -> 102260.27 | M17: 0.728 | N17: 6.92 | O17: 945 | P17: .ree | Q17: Halumbaro | R17: Reerican | S17: =SUM(F17*T17) -> 0
... A26: Acrola | B26: YOOT-nee-too | C26: /ˈjuːt.niː.tuː/ | D26: Trevilla | E26: =SUM(J26*K26) -> 10360.45 | F26: =SUM(G26*E26) -> 36590478 | G26: 3531.746 | H26: 90744386 | I26: =sum(H26/E26) -> 8758.7302 | J26: 19.01 | K26: 545 | L26: =SUM(K26*0.386102) -> 210.42559 | M26: 0.747 | N26: 6.12 | O26: 345 | P26: .tre | Q26: City Tirnsch | R26: Trevillian | S26: =SUM(F26*T26) -> 0
A27: N/a | D27: Totals | E27: =SUM(Acrola[Population]) -> 1070077951 | F27: =SUM(Acrola[GDP (Nominal)]) -> 5745716033804 | G27: =sum(Acrola[[#TOTALS],[GDP (Nominal)]]/Acrola[[#TOTALS],[Population]]) -> 5369.4369 | H27: =SUM(Acrola[GDP (PPP)]) -> 14211450824582 | I27: =sum(Acrola[[#TOTALS],[GDP (PPP)]]/Acrola[[#TOTALS],[Population]]) -> 13280.762 | J27: =sum(Acrola[[#TOTALS],[Population]]/Acrola[[#TOTALS],[Area (Km)]]) -> 59.484443 | K27: =SUM(Acrola[Area (Km)]) -> 17989207 | L27: =SUM(Acrola[Area (Mi)]) -> 6945668.8 | M27: N/a | N27: N/a | O27: N/a | P27: N/a | Q27: Suraspa | S27: =SUM(Acrola[Military]) -> 135069645564

Sheet Atirha
A1: Continent | B1: Pronunciation | C1: IPA Use (https://ipa-reader.com/) | D1: Name | E1: Population | F1: GDP (Nominal) | G1: Per (NOM) | H1: GDP (PPP) | I1: Per (PPP) | J1: Density | K1: Area (Km) | L1: Area (Mi) | M1: KTDI | N1: GDI | O1: Phone | P1: Domain | Q1: Capital | R1: Demonym | S1: Military | T1: Per GDP
A2: Atirha | B2: GEN-air | C2: /ˈdʒɛn.ɛr/ | D2: Geaiya | E2: =SUM(J2*K2) -> 9533899.7 | F2: =SUM(G2*E2) -> 187273030265 | G2: 19642.857 | H2: 2.0225487e+11 | I2: =sum(H2/E2) -> 21214.286 | J2: 2.7099 | K2: 3518174 | L2: =SUM(K2*0.386102) -> 1358374 | M2: 0.945 | N2: 8.44 | O2: 24 | P2: .gea | Q2: Tsyanka | R2: Geaiyan | S2: =SUM(F2*T2) -> 0
A3: Atirha | B3: TAYNG | C3: /teɪŋ/ | D3: Raledria | E3: =SUM(J3*K3) -> 3.0111528e+08 | F3: =SUM(G3*E3) -> 8579395623719 | G3: 28492.063 | H3: 8.5793956e+12 | I3: =sum(H3/E3) -> 28492.063 | J3: 127.8124 | K3: 2355916 | L3: =SUM(K3*0.386102) -> 909623.88 | M3: 0.942 | N3: 8.66 | O3: 20 | P3: .ral | Q3: Tirna | R3: Raledrian | S3: =SUM(F3*T3) -> 292557390769 | T3: 0.0341
A4: Atirha | B4: see-AH-nah | C4: /siːˈɑː.nə/ | D4: Etirha | E4: =SUM(J4*K4) -> 74667447 | F4: =SUM(G4*E4) -> 2642990568619 | G4: 35396.825 | H4: 2.1910392e+12 | I4: =sum(H4/E4) -> 29343.968 | J4: 40.0399 | K4: 1864826 | L4: =SUM(K4*0.386102) -> 720013.05 | M4: 0.969 | N4: 9.04 | O4: 22 | P4: .eti | Q4: Albiran | R4: Etirhan | S4: =SUM(F4*T4) -> 57617194396 | T4: 0.0218
A5: Atirha | B5: seh-LAH-jah | C5: /ˌsɛˈlɑː.dʒɑː/ | D5: Genaire | E5: =SUM(J5*K5) -> 15795087 | F5: =SUM(G5*E5) -> 294590913242 | G5: 18650.794 | H5: 4.3010273e+11 | I5: =sum(H5/E5) -> 27230.159 | J5: 8.8549 | K5: 1783768 | L5: =SUM(K5*0.386102) -> 688716.39 | M5: 0.874 | N5: 9.25 | O5: 27 | P5: .gen | Q5: Lishka | R5: Genairean | S5: =SUM(F5*T5) -> 0
A6: Atirha | B6: AR-bee-yah | C6: /ˈɑːr.bi.jə/ | D6: Laseltsh | E6: =SUM(J6*K6) -> 6524522.1 | F6: =SUM(G6*E6) -> 161300685473 | G6: 24722.222 | H6: 1.8388278e+11 | I6: =sum(H6/E6) -> 28183.333 | J6: 4.0803 | K6: 1599030 | L6: =SUM(K6*0.386102) -> 617388.68 | M6: 0.908 | N6: 7.39 | O6: 28 | P6: .las | Q6: Dariya | R6: Laseltshan | S6: =SUM(F6*T6) -> 0
A7: Atirha | B7: LEE-eh-ree | C7: /ˈliː.eɪ.ri/ | D7: New Misos | E7: =SUM(J7*K7) -> 53637198 | F7: =SUM(G7*E7) -> 834356411649 | G7: 15555.556 | H7: 1.2099396e+12 | I7: =sum(H7/E7) -> 22557.844 | J7: 45.8077 | K7: 1170921 | L7: =SUM(K7*0.386102) -> 452094.94 | M7: 0.868 | N7: 6.73 | O7: 26 | P7: .mis | Q7: Lunava | R7: Misoan | S7: =SUM(F7*T7) -> 14350930280 | T7: 0.0172
A8: Atirha | B8: VEH-roo-sah | C8: /ˈvɛr.uː.sɑː/ | D8: Arbiya | E8: =SUM(J8*K8) -> 6585930 | F8: =SUM(G8*E8) -> 96175485583 | G8: 14603.175 | H8: 1.5580429e+11 | I8: =sum(H8/E8) -> 23657.143 | J8: 11.9346 | K8: 551835 | L8: =SUM(K8*0.386102) -> 213064.6 | M8: 0.862 | N8: 6.91 | O8: 29 | P8: .arb | Q8: Kraevu | R8: Arbiyan | S8: =SUM(F8*T8) -> 0
A9: Atirha | B9: DAH-reh-wah | C9: /ˈdɑː.reɪ.wɑː/ | D9: Grazail | E9: =SUM(J9*K9) -> 3347590.2 | F9: =SUM(G9*E9) -> 34937151856 | G9: 10436.508 | H9: 5.3453842e+10 | I9: =sum(H9/E9) -> 15967.857 | J9: 16.5551 | K9: 202209 | L9: =SUM(K9*0.386102) -> 78073.299 | M9: 0.901 | N9: 8.59 | O9: 211 | P9: .gra | Q9: Mushira | R9: Grazailite | S9: =SUM(F9*T9) -> 0
A10: Atirha | B10: WUHN-dree | C10: /ˈwʌn.dri/ | D10: Disal Nila | E10: =SUM(J10*K10) -> 7438559.5 | F10: =SUM(G10*E10) -> 135192866449 | G10: 18174.603 | H10: 1.4465637e+11 | I10: =sum(H10/E10) -> 19446.825 | J10: 44.2666 | K10: 168040 | L10: =SUM(K10*0.386102) -> 64880.58 | M10: 0.955 | N10: 8.77 | O10: 213 | P10: .dis | Q10: Naliti | R10: Disali | S10: =SUM(F10*T10) -> 0
A11: Atirha | B11: oh-TEE-nah | C11: /ˌoʊˈtiː.nɑː/ | D11: Fincen | E11: =SUM(J11*K11) -> 4620319.8 | F11: =SUM(G11*E11) -> 59404111071 | G11: 12857.143 | H11: 7.6037262e+10 | I11: =sum(H11/E11) -> 16457.143 | J11: 35.0356 | K11: 131875 | L11: =SUM(K11*0.386102) -> 50917.201 | M11: 0.939 | N11: 7.68 | O11: 246 | P11: .fcn | Q11: Tiyomi | R11: Fincense | S11: =SUM(F11*T11) -> 0
A12: Atirha | B12: tay-OH-see-ah | C12: /ˌteɪˈoʊ.si.ə/ | D12: Phuris | E12: =SUM(J12*K12) -> 27120468 | F12: =SUM(G12*E12) -> 50581824409 | G12: 1865.0794 | H12: 1.5022802e+11 | I12: =sum(H12/E12) -> 5539.2857 | J12: 214.0729 | K12: 126688 | L12: =SUM(K12*0.386102) -> 48914.49 | M12: 0.736 | N12: 2.57 | O12: 711 | P12: .phu | Q12: City of Dauris | R12: Phurian | S12: =SUM(F12*T12) -> 0
A13: Atirha | B13: veh-soh-ZAH-tah | C13: /vɛ.soʊˈzɑː.tɑː/ | D13: Curata | E13: =SUM(J13*K13) -> 4523612.8 | F13: =SUM(G13*E13) -> 50800889917 | G13: 11230.159 | H13: 8.8393548e+10 | I13: =sum(H13/E13) -> 19540.476 | J13: 47.7406 | K13: 94754 | L13: =SUM(K13*0.386102) -> 36584.709 | M13: 0.856 | N13: 8.12 | O13: 247 | P13: .cur | Q13: Hulong | R13: Curatan | S13: =SUM(F13*T13) -> 0
A14: Atirha | B14: ZEH-nah-shahn | C14: /ˈzɛ.nɑː.ʃɑːn/ | D14: Pelan | E14: =SUM(J14*K14) -> 13705584 | F14: =SUM(G14*E14) -> 69071790646 | G14: 5039.6825 | H14: 1.0403009e+11 | I14: =sum(H14/E14) -> 7590.3439 | J14: 171.2299 | K14: 80042 | L14: =SUM(K14*0.386102) -> 30904.376 | M14: 0.668 | N14: 5.24 | O14: 210 | P14: .pla | Q14: Taoqu | R14: Pelani | S14: =SUM(F14*T14) -> 0
A15: Atirha | B15: EE-ah-ee-noh-ah | C15: /iːˌɑː.iˈnoʊ.ɑː/ | D15: Lasri | E15: =SUM(J15*K15) -> 2170549.5 | F15: =SUM(G15*E15) -> 18087912918 | G15: 8333.3333 | H15: 3.0387694e+10 | I15: =sum(H15/E15) -> 14000 | J15: 52.3617 | K15: 41453 | L15: =SUM(K15*0.386102) -> 16005.086 | M15: 0.883 | N15: 6.18 | O15: 242 | P15: .lar | Q15: Rukara | R15: Lasrian | S15: =SUM(F15*T15) -> 0
A16: Atirha | B16: GAL-kah | C16: /ˈɡæl.kɑː/ | D16: Peka | E16: =SUM(J16*K16) -> 1300163.5 | F16: =SUM(G16*E16) -> 18934920101 | G16: 14563.492 | H16: 2.6508888e+10 | I16: =sum(H16/E16) -> 20388.889 | J16: 38.1179 | K16: 34109 | L16: =SUM(K16*0.386102) -> 13169.553 | M16: 0.907 | N16: 7.85 | O16: 215 | P16: .pek | Q16: Kerefa | R16: Pekan | S16: =SUM(F16*T16) -> 0
A17: Atirha | B17: IK-zen | C17: /ˈɪk.zən/ | D17: Slyiaduun | E17: =SUM(J17*K17) -> 2166682.6 | F17: =SUM(G17*E17) -> 8683926123 | G17: 4007.9365 | H17: 2.0754583e+10 | I17: =sum(H17/E17) -> 9578.9683 | J17: 63.5279 | K17: 34106 | L17: =SUM(K17*0.386102) -> 13168.395 | M17: 0.762 | N17: 5.19 | O17: 245 | P17: .syl | Q17: Liaojin | R17: Slyiaduun | S17: =SUM(F17*T17) -> 0
A18: Atirha | B18: are-TOOR-lay | C18: /ɑːrˈtʊər.leɪ/ | D18: Aetintio | E18: =SUM(J18*K18) -> 1405386.8 | F18: =SUM(G18*E18) -> 10205784859 | G18: 7261.9048 | H18: 2.0819801e+10 | I18: =sum(H18/E18) -> 14814.286 | J18: 55.0506 | K18: 25529 | L18: =SUM(K18*0.386102) -> 9856.798 | M18: 0.815 | N18: 7.36 | O18: 241 | P18: .aet | Q18: Elora | R18: Aetintio | S18: =SUM(F18*T18) -> 0
A19: Atirha | B19: ek-SIL-ee-um | C19: /ˈɛk.sɪl.i.əm/ | D19: Metndria | E19: =SUM(J19*K19) -> 635532.16 | F19: =SUM(G19*E19) -> 2824587364 | G19: 4444.4444 | H19: 6.5530427e+09 | I19: =sum(H19/E19) -> 10311.111 | J19: 34.6509 | K19: 18341 | L19: =SUM(K19*0.386102) -> 7081.4968 | M19: 0.774 | N19: 6.92 | O19: 271 | P19: .met | Q19: Hidoro | R19: Metndrian | S19: =SUM(F19*T19) -> 0
... A21: Atirha | B21: KOH-ruch | C21: /ˈkɔː.rʊtʃ/ | D21: Tomscilus | E21: =SUM(J21*K21) -> 1158762.8 | F21: =SUM(G21*E21) -> 19450660950 | G21: 16785.714 | H21: 2.5480366e+10 | I21: =sum(H21/E21) -> 21989.286 | J21: 175.172 | K21: 6615 | L21: =SUM(K21*0.386102) -> 2554.0647 | M21: 0.914 | N21: 8.98 | O21: 243 | P21: .tom | Q21: Ternyu | R21: Tomscilian | S21: =SUM(F21*T21) -> 0
A22: N/a | D22: Totals | E22: =SUM(Atirha[Population]) -> 5.3828606e+08 | F22: =SUM(Atirha[GDP (Nominal)]) -> 13288249889282 | G22: =sum(Atirha[[#TOTALS],[GDP (Nominal)]]/Atirha[[#TOTALS],[Population]]) -> 24686.223 | H22: =SUM(Atirha[GDP (PPP)]) -> 13715532092913 | I22: =sum(Atirha[[#TOTALS],[GDP (PPP)]]/Atirha[[#TOTALS],[Population]]) -> 25480.006 | J22: =sum(Atirha[[#TOTALS],[Population]]/Atirha[[#TOTALS],[Area (Km)]]) -> 38.958749 | K22: =SUM(Atirha[Area (Km)]) -> 13816821 | L22: =SUM(Atirha[Area (Mi)]) -> 5334702.2 | M22: N/a | N22: N/a | O22: N/a | P22: N/a | Q22: Suraspa | S22: =SUM(Atirha[Military]) -> 364525515445

Sheet Ayuma
A1: Continent | B1: Pronunciation | C1: IPA Use (https://ipa-reader.com/) | D1: Name | E1: Population | F1: GDP (Nominal) | G1: Per (NOM) | H1: GDP (PPP) | I1: Per (PPP) | J1: Density | K1: Area (Km) | L1: Area (Mi) | M1: KTDI | N1: GDI | O1: Phone | P1: Domain | Q1: Capital | R1: Demonym | S1: Military | T1: Per GDP
A2: Ayuma | B2: SWEH-nahn | C2: /ˈswɛ.nɑːn/ | D2: Estijan | E2: =SUM(J2*K2) -> 2.6084482e+08 | F2: =SUM(G2*E2) -> 2805116867175 | G2: 10753.968 | H2: 5.0577732e+12 | I2: =sum(H2/E2) -> 19389.97 | J2: 35.873 | K2: 7271341 | L2: =SUM(K2*0.386102) -> 2807479.3 | M2: 0.825 | N2: 6.21 | O2: 30 | P2: .est | Q2: Shabiran | R2: Estijan | S2: =SUM(F2*T2) -> 65639734692 | T2: 0.0234
A3: Ayuma | B3: yoo-NY-ted MEE-hee-lee | C3: /juːˈnaɪ.tɪd ˈmiː.hi.liː/ | D3: Ealdorii | E3: =SUM(J3*K3) -> 1.3799264e+08 | F3: =SUM(G3*E3) -> 679011395990 | G3: 4920.6349 | H3: 1.548146e+12 | I3: =sum(H3/E3) -> 11219.048 | J3: 88.243 | K3: 1563780 | L3: =SUM(K3*0.386102) -> 603778.59 | M3: 0.78 | N3: 4.12 | O3: 32 | P3: .eal | Q3: Shurqan | R3: Ealdorii | S3: =SUM(F3*T3) -> 22339474928 | T3: 0.0329
A4: Ayuma | B4: TREE-an | C4: /ˈtriː.æn/ | D4: Emara | E4: =SUM(J4*K4) -> 90861040 | F4: =SUM(G4*E4) -> 2109274137239 | G4: 23214.286 | H4: 2.6936451e+12 | I4: =sum(H4/E4) -> 29645.766 | J4: 211.903 | K4: 428786 | L4: =SUM(K4*0.386102) -> 165555.13 | M4: 0.945 | N4: 7.64 | O4: 1 | P4: .ema | Q4: Rivostan | R4: Emaran | S4: =SUM(F4*T4) -> 53153708258 | T4: 0.0252
A5: Ayuma | B5: AM-chah | C5: /ˈæm.tʃɑː/ | D5: Ukhdari | E5: =SUM(J5*K5) -> 85678806 | F5: =SUM(G5*E5) -> 962186588641 | G5: 11230.159 | H5: 1.7687012e+12 | I5: =sum(H5/E5) -> 20643.392 | J5: 109.339 | K5: 783607 | L5: =SUM(K5*0.386102) -> 302552.23 | M5: 0.834 | N5: 7.02 | O5: 17 | P5: .ukh | Q5: Faramozan | R5: Ukhdari | S5: =SUM(F5*T5) -> 17319358596 | T5: 0.018
A6: Ayuma | B6: NEE-ah | C6: /ˈniː.ɑː/ | D6: Lycroa | E6: =SUM(J6*K6) -> 81313729 | F6: =SUM(G6*E6) -> 1677902350965 | G6: 20634.921 | H6: 2.1289136e+12 | I6: =sum(H6/E6) -> 26181.477 | J6: 164.407 | K6: 494588 | L6: =SUM(K6*0.386102) -> 190961.42 | M6: 0.939 | N6: 8.46 | O6: 19 | P6: .lyc | Q6: Jungui | R6: Lycroan | S6: =SUM(F6*T6) -> 23994003619 | T6: 0.0143
A7: Ayuma | B7: SHOM-jind | C7: /ˈʃɒm.dʒɪnd/ | D7: Verusa | E7: =SUM(J7*K7) -> 69480631 | F7: =SUM(G7*E7) -> 1549528349095 | G7: 22301.587 | H7: 1.8682335e+12 | I7: =sum(H7/E7) -> 26888.552 | J7: 95.1 | K7: 730606 | L7: =SUM(K7*0.386102) -> 282088.44 | M7: 0.974 | N7: 9.59 | O7: 12 | P7: .ver | Q7: Huifarn | R7: Verusan | S7: =SUM(F7*T7) -> 18594340189 | T7: 0.012
A8: Ayuma | B8: AY-tin-tee-oh | C8: /ˈeɪ.tɪn.ti.oʊ/ | D8: Siana | E8: =SUM(J8*K8) -> 39335005 | F8: =SUM(G8*E8) -> 750799098487 | G8: 19087.302 | H8: 8.6581508e+11 | I8: =sum(H8/E8) -> 22011.312 | J8: 129.738 | K8: 303188 | L8: =SUM(K8*0.386102) -> 117061.49 | M8: 0.96 | N8: 9.67 | O8: 13 | P8: .sia | Q8: Wadika | R8: Sianan | S8: =SUM(F8*T8) -> 8258790083 | T8: 0.011
A9: Ayuma | B9: SHEE-nahm | C9: /ˈʃiː.nɑːm/ | D9: Praesy | E9: =SUM(J9*K9) -> 39227750 | F9: =SUM(G9*E9) -> 555726454508 | G9: 14166.667 | H9: 7.9245977e+11 | I9: =sum(H9/E9) -> 20201.51 | J9: 77.41 | K9: 506753 | L9: =SUM(K9*0.386102) -> 195658.35 | M9: 0.911 | N9: 7.11 | O9: 14 | P9: .pra | Q9: Brimasha | R9: Praesian | S9: =SUM(F9*T9) -> 8558187399 | T9: 0.0154
A10: Ayuma | B10: PEH-li-neez | C10: /ˈpɛl.iːnz/ | D10: Easuhura | E10: =SUM(J10*K10) -> 29913650 | F10: =SUM(G10*E10) -> 747841249925 | G10: 25000 | H10: 9.0488791e+11 | I10: =sum(H10/E10) -> 30250 | J10: 273.007 | K10: 109571 | L10: =SUM(K10*0.386102) -> 42305.582 | M10: 0.947 | N10: 8.56 | O10: 11 | P10: .eas | Q10: Tanbai | R10: Easuhuran | S10: =SUM(F10*T10) -> 24005704123 | T10: 0.0321
A11: Ayuma | B11: NAY-es see | C11: /ˈneɪ.ɛs siː/ | D11: Merela Sta | E11: =SUM(J11*K11) -> 23361657 | F11: =SUM(G11*E11) -> 331883853602 | G11: 14206.349 | H11: 4.8144901e+11 | I11: =sum(H11/E11) -> 20608.513 | J11: 137.449 | K11: 169966 | L11: =SUM(K11*0.386102) -> 65624.213 | M11: 0.929 | N11: 8.73 | O11: 12 | P11: .mer | Q11: Talung | R11: Merelan | S11: =SUM(F11*T11) -> 4380866868 | T11: 0.0132
A12: Ayuma | B12: sah-DAYN | C12: /ˈsɑː.deɪn/ | D12: Hkuqo | E12: =SUM(J12*K12) -> 22833760 | F12: =SUM(G12*E12) -> 67051518611 | G12: 2936.5079 | H12: 2.4473804e+11 | I12: =sum(H12/E12) -> 10718.254 | J12: 61.596 | K12: 370702 | L12: =SUM(K12*0.386102) -> 143128.78 | M12: 0.715 | N12: 5.38 | O12: 120 | P12: .hku | Q12: Tanshiva | R12: Hkuqoan | S12: =SUM(F12*T12) -> 0
A13: Ayuma | B13: LID-roh-ah | C13: /ˈlɪd.roʊ.ɑː/ | D13: Heiso | E13: =SUM(J13*K13) -> 20605956 | F13: =SUM(G13*E13) -> 97305904580 | G13: 4722.2222 | H13: 2.5688759e+11 | I13: =sum(H13/E13) -> 12466.667 | J13: 61.596 | K13: 334534 | L13: =SUM(K13*0.386102) -> 129164.25 | M13: 0.709 | N13: 3.09 | O13: 388 | P13: .hei | Q13: Mivlo | R13: Heisan | S13: =SUM(F13*T13) -> 0
A14: Ayuma | B14: nyoo MEE-sos | C14: /njuː ˈmiː.sɒs/ | D14: Darewa | E14: =SUM(J14*K14) -> 19678480 | F14: =SUM(G14*E14) -> 220992451374 | G14: 11230.159 | H14: 4.0662611e+11 | I14: =sum(H14/E14) -> 20663.492 | J14: 28.873 | K14: 681553 | L14: =SUM(K14*0.386102) -> 263148.98 | M14: 0.836 | N14: 7.88 | O14: 35 | P14: .dar | Q14: Shamarin | R14: Darewan | S14: =SUM(F14*T14) -> 0
A15: Ayuma | B15: DI-sahl NEE-lah | C15: /ˈdɪ.sɑːl ˈniː.lɑː/ | D15: Lydroa | E15: =SUM(J15*K15) -> 18995781 | F15: =SUM(G15*E15) -> 122869538686 | G15: 6468.254 | H15: 2.8997211e+11 | I15: =sum(H15/E15) -> 15265.079 | J15: 70.833 | K15: 268177 | L15: =SUM(K15*0.386102) -> 103543.68 | M15: 0.756 | N15: 6.84 | O15: 36 | P15: .lyd | Q15: Zarfan | R15: Lydroan | S15: =SUM(F15*T15) -> 0
A16: Ayuma | B16: FAR lands | C16: /fɑːr lændz/ | D16: Yaxuto | E16: =SUM(J16*K16) -> 18401158 | F16: =SUM(G16*E16) -> 340275383450 | G16: 18492.063 | H16: 4.3256626e+11 | I16: =sum(H16/E16) -> 23507.556 | J16: 103.175 | K16: 178349 | L16: =SUM(K16*0.386102) -> 68860.906 | M16: 0.902 | N16: 8.85 | O16: 15 | P16: .yax | Q16: Khorin | R16: Yaxutan | S16: =SUM(F16*T16) -> 5682598904 | T16: 0.0167
A17: Ayuma | B17: peh-LOO-groh-toh-uh | C17: /pɛˈluː.groʊ.toʊ.ə/ | D17: Acrana | E17: =SUM(J17*K17) -> 14469041 | F17: =SUM(G17*E17) -> 128039530617 | G17: 8849.2063 | H17: 2.0870443e+11 | I17: =sum(H17/E17) -> 14424.206 | J17: 109.727 | K17: 131864 | L17: =SUM(K17*0.386102) -> 50912.954 | M17: 0.89 | N17: 6.43 | O17: 17 | P17: .acr | Q17: Samaru | R17: Acranan | S17: =SUM(F17*T17) -> 0
A18: Ayuma | B18: MEH-reh-lah STAH | C18: /ˈmɛr.ə.lɑː stɑː/ | D18: Fermori | E18: =SUM(J18*K18) -> 12299328 | F18: =SUM(G18*E18) -> 113231906417 | G18: 9206.3492 | H18: 1.8003873e+11 | I18: =sum(H18/E18) -> 14638.095 | J18: 57.366 | K18: 214401 | L18: =SUM(K18*0.386102) -> 82780.655 | M18: 0.895 | N18: 9.77 | O18: 178 | P18: .fer | Q18: Khalviro | R18: Fermorian | S18: =SUM(F18*T18) -> 0
A19: Ayuma | B19: tveh-KOH-kah | C19: /ˌtvɛˈkoʊ.kɑː/ | D19: Zenashan | E19: =SUM(J19*K19) -> 9819273 | F19: =SUM(G19*E19) -> 28444719379 | G19: 2896.8254 | H19: 7.3387376e+10 | I19: =sum(H19/E19) -> 7473.8095 | J19: 185.161 | K19: 53031 | L19: =SUM(K19*0.386102) -> 20475.375 | M19: 0.729 | N19: 5.06 | O19: 821 | P19: .zen | Q19: Zirafu | R19: Zenashan | S19: =SUM(F19*T19) -> 0
A20: Ayuma | B20: EH-treh-tez | C20: /ˈɛ.trɛ.tɛz/ | D20: Eldjo | E20: =SUM(J20*K20) -> 5393380.3 | F20: =SUM(G20*E20) -> 74265990914 | G20: 13769.841 | H20: 1.2328154e+11 | I20: =sum(H20/E20) -> 22857.937 | J20: 41.196 | K20: 130920 | L20: =SUM(K20*0.386102) -> 50548.474 | M20: 0.86 | N20: 8.03 | O20: 18 | P20: .eld | Q20: Shorakim | R20: Eldjan | S20: =SUM(F20*T20) -> 0
A21: Ayuma | B21: RY-new | C21: /ˈraɪ.njuː/ | D21: Uularin | E21: =SUM(J21*K21) -> 5001934.2 | F21: =SUM(G21*E21) -> 36522059567 | G21: 7301.5873 | H21: 82174634025 | I21: =sum(H21/E21) -> 16428.571 | J21: 41.965 | K21: 119193 | L21: =SUM(K21*0.386102) -> 46020.656 | M21: 0.773 | N21: 6.78 | O21: 37 | P21: .uul | Q21: Zahlim | R21: Uularini | S21: =SUM(F21*T21) -> 0
A22: Ayuma | B22: NORTH air | C22: /nɔːrθ ɛər/ | D22: Ilicuhe | E22: =SUM(J22*K22) -> 3254988.2 | F22: =SUM(G22*E22) -> 95970484448 | G22: 29484.127 | H22: 8.2150735e+10 | I22: =sum(H22/E22) -> 25238.413 | J22: 118.187 | K22: 27541 | L22: =SUM(K22*0.386102) -> 10633.635 | M22: 0.958 | N22: 8.14 | O22: 111 | P22: .ili | Q22: Sakhen | R22: Ilicuhan | S22: =SUM(F22*T22) -> 0
A23: Ayuma | B23: FIN-sen | C23: /ˈfɪn.sən/ | D23: Palina | E23: =SUM(J23*K23) -> 3123402.5 | F23: =SUM(G23*E23) -> 46355258850 | G23: 14841.27 | H23: 6.4168414e+10 | I23: =sum(H23/E23) -> 20544.395 | J23: 71.996 | K23: 43383 | L23: =SUM(K23*0.386102) -> 16750.263 | M23: 0.865 | N23: 7.95 | O23: 101 | P23: .pal | Q23: Lahzhao | R23: Palinian | S23: =SUM(F23*T23) -> 0
A24: Ayuma | B24: VOLL-ver | C24: /ˈvɒl.vər/ | D24: Ikzen | E24: =SUM(J24*K24) -> 3103321.8 | F24: =SUM(G24*E24) -> 6773122889 | G24: 2182.5397 | H24: 1.984525e+10 | I24: =sum(H24/E24) -> 6394.8413 | J24: 1.54 | K24: 2015144 | L24: =SUM(K24*0.386102) -> 778051.13 | M24: 0.664 | N24: 5.91 | O24: 333 | P24: .ikz | Q24: Velotha | R24: Ikzener | S24: =SUM(F24*T24) -> 0
A25: Ayuma | B25: DOO-al SEN-ree-uh | C25: /ˈduː.əl ˈsɛn.ri.ə/ | D25: Danocia | E25: =SUM(J25*K25) -> 2020940.1 | F25: =SUM(G25*E25) -> 5453330361 | G25: 2698.4127 | H25: 1.3796926e+10 | I25: =sum(H25/E25) -> 6826.9841 | J25: 2.695 | K25: 749885 | L25: =SUM(K25*0.386102) -> 289532.1 | M25: 0.741 | N25: 3.27 | O25: 31 | P25: .dan | Q25: Tazmirak | R25: Danocian | S25: =SUM(F25*T25) -> 0
A26: Ayuma | B26: NEE-reh-TOO-ee and AH-noo-lahn | C26: /ˌniː.rɛˈtuː.i ænd ˈɑː.nuː.lɑːn/ | D26: Urbiqu | E26: =SUM(J26*K26) -> 1914198.4 | F26: =SUM(G26*E26) -> 3418211500 | G26: 1785.7143 | H26: 9502627970 | I26: =sum(H26/E26) -> 4964.2857 | J26: 1.54 | K26: 1242986 | L26: =SUM(K26*0.386102) -> 479919.38 | M26: 0.695 | N26: 2.3 | O26: 133 | P26: .urb | Q26: Alshira | R26: Urbiquan | S26: =SUM(F26*T26) -> 0
A27: Ayuma | B27: oo-MAR-see-ah | C27: /ˌuːˈmɑːr.si.ə/ | D27: Koruch | E27: =SUM(J27*K27) -> 820937.43 | F27: =SUM(G27*E27) -> 14985365694 | G27: 18253.968 | H27: 1.3786536e+10 | I27: =sum(H27/E27) -> 16793.651 | J27: 1.925 | K27: 426461 | L27: =SUM(K27*0.386102) -> 164657.45 | M27: 0.93 | N27: 9.69 | O27: 145 | P27: .kor | Q27: Basturah | R27: Koruchi | S27: =SUM(F27*T27) -> 0
A28: Ayuma | B28: JAY-shayn | C28: /dʒeɪ.ʃeɪn/ | D28: Niul Spijan | E28: =SUM(J28*K28) -> 220217.6 | F28: =SUM(G28*E28) -> 7.6027505e+08 | G28: 3452.381 | H28: 2.5849352e+09 | I28: =sum(H28/E28) -> 11738.095 | J28: 12.16 | K28: 18110 | L28: =SUM(K28*0.386102) -> 6992.3072 | M28: 0.562 | N28: 5.2 | O28: 34 | P28: .niu | Q28: Chludu Ura | R28: Spijani | S28: =SUM(F28*T28) -> 0
... A30: Ayuma | B30: FAY-oh LYE | C30: /ˈfeɪ.oʊ laɪ/ | D30: New Kizura | E30: =SUM(J30*K30) -> 133064.86 | F30: =SUM(G30*E30) -> 5438761931 | G30: 40873.016 | H30: 4.3618871e+09 | I30: =sum(H30/E30) -> 32780.159 | J30: 0.385 | K30: 345623 | L30: =SUM(K30*0.386102) -> 133445.73 | M30: 0.952 | N30: 9.35 | O30: 33 | P30: .kiz | Q30: New Kizura | R30: Kizuran | S30: =SUM(F30*T30) -> 0
A31: N/a | D31: Totals | E31: =SUM(Auyma[Population]) -> 1020242809 | F31: =SUM(Auyma[GDP (Nominal)]) -> 13577578364819 | G31: =sum(Auyma[[#TOTALS],[GDP (Nominal)]]/Auyma[[#TOTALS],[Population]]) -> 13308.183 | H31: =SUM(Auyma[GDP (PPP)]) -> 20619054928270 | I31: =sum(Auyma[[#TOTALS],[GDP (PPP)]]/Auyma[[#TOTALS],[Population]]) -> 20209.949 | J31: =sum(Auyma[[#TOTALS],[Population]]/Auyma[[#TOTALS],[Area (Km)]]) -> 51.694421 | K31: =SUM(Auyma[Area (Km)]) -> 19736033 | L31: =SUM(Auyma[Area (Mi)]) -> 7620121.8 | M31: N/a | N31: N/a | O31: N/a | P31: N/a | Q31: Suraspa | S31: =SUM(Auyma[Military]) -> 251926767658

Sheet Mahea
A1: Continent | B1: Pronunciation | C1: IPA Use (https://ipa-reader.com/) | D1: Name | E1: Population | F1: GDP (Nominal) | G1: Per (NOM) | H1: GDP (PPP) | I1: Per (PPP) | J1: Density | K1: Area (Km) | L1: Area (Mi) | M1: KTDI | N1: GDI | O1: Phone | P1: Domain | Q1: Capital | R1: Demonym | S1: Military | T1: Per GDP
A2: Mahea | B2: AH-krah-nah | C2: /ɑːˈkrɑː.nə/ | D2: Inania | E2: =SUM(J2*K2) -> 2.3647557e+08 | F2: =SUM(G2*E2) -> 741332141580 | G2: 3134.9206 | H2: 2.1350366e+12 | I2: =sum(H2/E2) -> 9028.5714 | J2: 79.7716 | K2: 2964408 | L2: =SUM(K2*0.386102) -> 1144563.9 | M2: 0.769 | N2: 6.43 | O2: 902 | P2: .ina | Q2: Fashti | R2: Inanian | S2: =SUM(F2*T2) -> 12750912835 | T2: 0.0172
A3: Mahea | B3: pah-LEE-nah | C3: /ˌpɑːˈliː.nɑː/ | D3: Pelugrotoa | E3: =SUM(J3*K3) -> 3.4752059e+08 | F3: =SUM(G3*E3) -> 4121980291974 | G3: 11861.111 | H3: 7.4607843e+12 | I3: =sum(H3/E3) -> 21468.611 | J3: 134.5993 | K3: 2581890 | L3: =SUM(K3*0.386102) -> 996872.89 | M3: 0.839 | N3: 2.33 | O3: 901 | P3: .pel | Q3: Thavrin | R3: Pelugrotoan | S3: =SUM(F3*T3) -> 176420756497 | T3: 0.0428
A4: Mahea | B4: ROO-eel-koo | C4: /ˈruː.iːl.kuː/ | D4: Ocaun | E4: =SUM(J4*K4) -> 88913943 | F4: =SUM(G4*E4) -> 43398472202 | G4: 488.09524 | H4: 2.7384436e+11 | I4: =sum(H4/E4) -> 3079.881 | J4: 63.5228 | K4: 1399717 | L4: =SUM(K4*0.386102) -> 540433.53 | M4: 0.396 | N4: 0.61 | O4: 999 | P4: .oca | Q4: Kejira | R4: Ocunese | S4: =SUM(F4*T4) -> 5294613609 | T4: 0.122
A5: Mahea | B5: SLY-ah-doon | C5: /ˈslaɪ.ɑː.duːn/ | D5: Sivoso | E5: =SUM(J5*K5) -> 21995119 | F5: =SUM(G5*E5) -> 81434311263 | G5: 3702.381 | H5: 2.0195709e+11 | I5: =sum(H5/E5) -> 9181.9048 | J5: 16.5544 | K5: 1328657 | L5: =SUM(K5*0.386102) -> 512997.12 | M5: 0.745 | N5: 5.49 | O5: 905 | P5: .siv | Q5: Amrata | R5: Sivosan | S5: =SUM(F5*T5) -> 0
A6: Mahea | B6: VAY-veh-lay | C6: /ˈveɪ.vɛl.eɪ/ | D6: Dual Cenryia | E6: =SUM(J6*K6) -> 95001457 | F6: =SUM(G6*E6) -> 313278613382 | G6: 3297.619 | H6: 1.0056243e+12 | I6: =sum(H6/E6) -> 10585.357 | J6: 92.3976 | K6: 1028181 | L6: =SUM(K6*0.386102) -> 396982.74 | M6: 0.738 | N6: 4.29 | O6: 923 | P6: .cen | Q6: Vrandig | R6: Cenryi | S6: =SUM(F6*T6) -> 7863293196 | T6: 0.0251
A7: Mahea | B7: GIZE | C7: /ɡaɪz/ | D7: Taoisia | E7: =SUM(J7*K7) -> 11247660 | F7: =SUM(G7*E7) -> 20040472905 | G7: 1781.746 | H7: 6.0923038e+10 | I7: =sum(H7/E7) -> 5416.5079 | J7: 11.9353 | K7: 942386 | L7: =SUM(K7*0.386102) -> 363857.12 | M7: 0.643 | N7: 3.65 | O7: 928 | P7: .tao | Q7: Kumazi | R7: Taoisian | S7: =SUM(F7*T7) -> 0
A8: Mahea | B8: TOM-sih-lus | C8: /ˈtɒm.sɪ.ləs/ | D8: Seytinemas | E8: =SUM(J8*K8) -> 71957346 | F8: =SUM(G8*E8) -> 790959715767 | G8: 10992.063 | H8: 1.4790947e+12 | I8: =sum(H8/E8) -> 20555.159 | J8: 82.0123 | K8: 877397 | L8: =SUM(K8*0.386102) -> 338764.74 | M8: 0.832 | N8: 6.08 | O8: 921 | P8: .sey | Q8: Vulna | R8: Seytinemese | S8: =SUM(F8*T8) -> 49118598349 | T8: 0.0621
A9: Mahea | B9: PROO-im FEE-jahn | C9: /ˈpruː.ɪm ˈfiː.dʒɑːn/ | D9: Sunsokua | E9: =SUM(J9*K9) -> 79558877 | F9: =SUM(G9*E9) -> 1000800162006 | G9: 12579.365 | H9: 1401120226808 | I9: =sum(H9/E9) -> 17611.111 | J9: 107.8092 | K9: 737960 | L9: =SUM(K9*0.386102) -> 284927.83 | M9: 0.918 | N9: 8.92 | O9: 744 | P9: .sun | Q9: Mikalu | R9: Sunsokuan | S9: =SUM(F9*T9) -> 45936727436 | T9: 0.0459
A10: Mahea | B10: MEN-deh-rayd | C10: /ˌmɛn.dəˈreɪd/ | D10: Lieri | E10: =SUM(J10*K10) -> 36478307 | F10: =SUM(G10*E10) -> 33872714074 | G10: 928.57143 | H10: 1.1076378e+11 | I10: =sum(H10/E10) -> 3036.4286 | J10: 61.9886 | K10: 588468 | L10: =SUM(K10*0.386102) -> 227208.67 | M10: 0.602 | N10: 2.05 | O10: 906 | P10: .lie | Q10: Nabruik | R10: Lierin | S10: =SUM(F10*T10) -> 0
A11: Mahea | B11: ZHAN-sheh | C11: /ˈʒɑːn.ʃeɪ/ | D11: Vayvele | E11: =SUM(J11*K11) -> 74436761 | F11: =SUM(G11*E11) -> 652798578359 | G11: 8769.8413 | H11: 1.0771177e+12 | I11: =sum(H11/E11) -> 14470.238 | J11: 128.9788 | K11: 577124 | L11: =SUM(K11*0.386102) -> 222828.73 | M11: 0.887 | N11: 7.84 | O11: 908 | P11: .vay | Q11: Kaisri | R11: Vayvelean | S11: =SUM(F11*T11) -> 10705896685 | T11: 0.0164
A12: Mahea | B12: EH-teer-hah | C12: /ˈɛ.tɪər.hɑː/ | D12: Byllu | E12: =SUM(J12*K12) -> 9106538.7 | F12: =SUM(G12*E12) -> 12611833376 | G12: 1384.9206 | H12: 3.5691488e+10 | I12: =sum(H12/E12) -> 3919.3254 | J12: 16.1605 | K12: 563506 | L12: =SUM(K12*0.386102) -> 217570.79 | M12: 0.687 | N12: 4.91 | O12: 925 | P12: .byl | Q12: Dundryan | R12: Kiesian | S12: =SUM(F12*T12) -> 0
A13: Mahea | B13: AS-tee | C13: /ˈæs.ti/ | D13: Exilium | E13: =SUM(J13*K13) -> 25083674 | F13: =SUM(G13*E13) -> 43697352283 | G13: 1742.0635 | H13: 1.2628535e+11 | I13: =sum(H13/E13) -> 5034.5635 | J13: 55.4426 | K13: 452426 | L13: =SUM(K13*0.386102) -> 174682.58 | M13: 0.673 | N13: 5.62 | O13: 913 | P13: .exi | Q13: Dulvasra | R13: Exilian | S13: =SUM(F13*T13) -> 0
A14: Mahea | B14: GAY-ee-yah | C14: /ˈɡeɪ.i.jɑː/ | D14: Inrea | E14: =SUM(J14*K14) -> 2051969.9 | F14: =SUM(G14*E14) -> 26789607289 | G14: 13055.556 | H14: 3.1343841e+10 | I14: =sum(H14/E14) -> 15275 | J14: 5.005 | K14: 409984 | L14: =SUM(K14*0.386102) -> 158295.64 | M14: 0.841 | N14: 2.76 | O14: 914 | P14: .inr | Q14: Dalsjiv | R14: Inrean | S14: =SUM(F14*T14) -> 0
A15: Mahea | B15: MEE-go-koo | C15: /ˈmiː.goʊ.kuː/ | D15: Trian | E15: =SUM(J15*K15) -> 27844193 | F15: =SUM(G15*E15) -> 432026969545 | G15: 15515.873 | H15: 6.7701475e+11 | I15: =sum(H15/E15) -> 24314.396 | J15: 72.7656 | K15: 382656 | L15: =SUM(K15*0.386102) -> 147744.25 | M15: 0.847 | N15: 7.03 | O15: 903 | P15: .tri | Q15: Treka | R15: Trian | S15: =SUM(F15*T15) -> 9202174451 | T15: 0.0213
