Workbook

Sheet GlobalContinent Population
A1: E | B1: A | C1: Global Population | D1: Global Population Growth | K1: E | L1: A | M1: Acrolan Population | N1: Acrolan Population Growth | O1: % of World | V1: E | W1: A | X1: Atirhan Population | Y1: Atirhan Population Growth | Z1: % of World | AG1: E | AH1: A | AI1: Ayuman Population | AJ1: Ayuma Population Growth | AK1: % of World | AR1: E | AS1: A | AT1: Mahean Population | AU1: Mahean Population Growth | AV1: % of World | BC1: E | BD1: A | BE1: Massiran Population | BF1: Massiran Population Growth | BG1: % of World | BN1: E | BO1: A | BP1: New Ayren Population | BQ1: New Ayren Population Growth | BR1: % of World | BY1: E | BZ1: A | CA1: Quian Population | CB1: Quian Population Growth | CC1: % of World
A2: =SUM(B2+250) -> 2015 | B2: 1765 | C2: =Acetoa!C2 + Acrana!C2 + Aetintio!C2 + Ahokini!C2 + Amcha!C2 + Andsaudare!C2 + Anymna!C2 + Aplasia!C2 + Arbiya!C2 + 'Areoix Lie'!C2 + Ashain!C2 + Astye!C2 + Baluyde!C2 + Byllu!C2 + 'Candenat'!C2 + 'Canldives'!C2 + 'Chaenia'!C2 + 'Cloja'!C2 + 'Crila Republic'!C2 + 'Cruthi Anoso'!C2 + 'Curata'!C2 + Dahe!C2 + Danocia!C2 + Darewa!C2 + Desaki!C2 + Deschon!C2 + 'Disal Nila'!C2 + 'Dual Cenryia'!C2 + Ealdorii!C2 + Easuhura!C2 + Eldavpir!C2 + Eldjo!C2 + 'Elja and Munusia'!C2 + Emara!C2 + Enina!C2 + Eparia!C2 + Erkizil!C2 + Estijan!C2 + Etirha!C2 + Etretes!C2 + Exilium!C2 + 'Far Lands'!C2 + 'Feio Lie'!C2 + Fermori!C2 + Finae!C2 + Fincen!C2 + 'Fire Coast'!C2 + Gaeiya!C2 + Galca!C2 + Genaire!C2 + Grazail!C2 + Guise!C2 + Haiza!C2 + Heiso!C2 + Hiwush!C2 + Hkuqo!C2 + Hyelen!C2 + Iainoa!C2 + Iareva!C2 + Ihner!C2 + Ikzen!C2 + Ilicuhe!C2 + Inania!C2 + Inrea!C2 + Iquir!C2 + Isari!C2 + Isnti!C2 + Isuibul!C2 + Jathua!C2 + Jau!C2 + Jshain!C2 + Kaastini!C2 + Koruch!C2 + Kusierna!C2 + Laselteh!C2 + Lasri!C2 + Letan!C2 + Lieri!C2 + Lycroa!C2 + Lydroa!C2 + Maalle!C2 + Mendereide!C2 + 'Merela Sta'!C2 + 'Mesjan Hyaa'!C2 + Metndria!C2 + Migoku!C2 + Myla!C2 + 'New Kizura'!C2 + 'New Misos'!C2 + 'Nheyes Si'!C2 + Nia!C2 + 'Niretui and Anulan'!C2 + 'Niul Spijan'!C2 + 'North Ayre'!C2 + Ocaun!C2 + Ohtina!C2 + Onphello!C2 + Oscairia!C2 + Othya!C2 + Otiiric!C2 + Oyreain!C2 + Ozinia!C2 + Palina!C2 + Peka!C2 + Pelan!C2 + Pelines!C2 + Pelugrotoa!C2 + 'Pha Hii'!C2 + Phuris!C2 + Praesyu!C2 + Prstreula!C2 + 'Pruim Fijan'!C2 + 'Prystr Hii'!C2 + Quidic!C2 + 'Raledria'!C2 + 'Reerica'!C2 + 'Rethern'!C2 + 'Rijan bu'!C2 + 'Rinew'!C2 + 'Rkmepuia'!C2 + 'Rtesania'!C2 + 'Ruylku'!C2 + Saa!C2 + Sadain!C2 + Sanagara!C2 + Sattle!C2 + Selaja!C2 + Seytinemas!C2 + Shinam!C2 + Shomjind!C2 + Siana!C2 + Sivoso!C2 + Slyiaduun!C2 + Stinebar!C2 + Suenan!C2 + Sunsokua!C2 + Taing!C2 + Taniduna!C2 + Taoisia!C2 + Taval!C2 + Terressin!C2 + Tomscilus!C2 + Tonder!C2 + Trevilla!C2 + Trian!C2 + Tvecoca!C2 + Ucrua!C2 + Ukhdari!C2 + Umarcia!C2 + Umendel!C2 + 'United Delet'!C2 + 'United Mihili'!C2 + Urbiqu!C2 + Uularin!C2 + Vayvele!C2 + Veelmit!C2 + Verste!C2 + Verusa!C2 + Vesozata!C2 + Viussi!C2 + Volver!C2 + Walporein!C2 + 'Welenu Fana'!C2 + 'Western Migoku'!C2 + Wundry!C2 + Yaxuto!C2 + Yihnurda!C2 + Yoprioq!C2 + Yutnitu!C2 + Zenashan!C2 + Zhanshe!C2 + Ztesh!C2 -> 6.8491801e+09 | D2: =((C2-C3)/C3) -> 0.0096461647 | K2: =SUM(L2+250) -> 2015 | L2: 1765 | M2: ='Areoix Lie'!C2 + Pelines!C2 + Terressin!C2 + Taniduna!C2 + Iquir!C2 + Deschon!C2 + Othya!C2 + Eldavpir!C2 + 'Candenat'!C2 + Jau!C2 + Viussi!C2 + Jathua!C2 + Jshain!C2 + Acetoa!C2 + Sattle!C2 + 'Reerica'!C2 + 'Feio Lie'!C2 + Umendel!C2 + 'Fire Coast'!C2 + Yoprioq!C2 + 'Rijan bu'!C2 + Saa!C2 + 'Rinew'!C2 + Enina!C2 + Trevilla!C2 -> 1.0700681e+09 | N2: =((M2-M3)/M3) -> 0.011979006 | O2: =SUM(M2/C2) -> 0.15623303 | V2: =SUM(W2+250) -> 2015 | W2: 1765 | X2: =Aetintio!C2 + Arbiya!C2 + 'Curata'!C2 + 'Disal Nila'!C2 + Etirha!C2 + Fincen!C2 + Gaeiya!C2 + Genaire!C2 + Grazail!C2 + Guise!C2 + Laselteh!C2 + Lasri!C2 + Metndria!C2 + 'New Misos'!C2 + Peka!C2 + Pelan!C2 + Phuris!C2 + 'Raledria'!C2 + Slyiaduun!C2 + Tomscilus!C2 -> 5.3743781e+08 | Y2: =((X2-X3)/X3) -> 0.011148887 | Z2: =SUM(X2/C2) -> 0.078467466 | AG2: =SUM(AH2+250) -> 2015 | AH2: 1765 | AI2: =Acrana!C2 + Danocia!C2 + Darewa!C2 + Ealdorii!C2 + Easuhura!C2 + Eldjo!C2 + Emara!C2 + Estijan!C2 + Fermori!C2 + Ikzen!C2 + Ilicuhe!C2 + Koruch!C2 + Lycroa!C2 + Lydroa!C2 + 'Merela Sta'!C2 + 'New Kizura'!C2 + 'Niul Spijan'!C2 + Palina!C2 + Praesyu!C2 + Siana!C2 + Tonder!C2 + Ukhdari!C2 + Urbiqu!C2 + Uularin!C2 + Verusa!C2 + Yaxuto!C2 + Zenashan!C2 + Hkuqo!C2 -> 9.9965908e+08 | AJ2: =((AI2-AI3)/AI3) -> 0.0066254716 | AK2: =SUM(AI2/C2) -> 0.1459531 | AR2: =SUM(AS2+250) -> 2015 | AS2: 1765 | AT2: =Amcha!C2 + Byllu!C2 + 'Chaenia'!C2 + 'Cruthi Anoso'!C2 + 'Dual Cenryia'!C2 + Exilium!C2 + Galca!C2 + Inania!C2 + Inrea!C2 + Isnti!C2 + Lieri!C2 + Ocaun!C2 + Otiiric!C2 + Ozinia!C2 + Pelugrotoa!C2 + 'Rtesania'!C2 + Sadain!C2 + Selaja!C2 + Seytinemas!C2 + Sivoso!C2 + Sunsokua!C2 + Taing!C2 + Taoisia!C2 + Trian!C2 + Vayvele!C2 -> 1.3873282e+09 | AU2: =((AT2-AT3)/AT3) -> 0.0097958061 | AV2: =SUM(AT2/C2) -> 0.2025539 | BC2: =SUM(BD2+250) -> 2015 | BD2: 1765 | BE2: ='Canldives'!C2 + 'Cloja'!C2 + Dahe!C2 + Eparia!C2 + Etretes!C2 + Haiza!C2 + Ihner!C2 + Kaastini!C2 + Kusierna!C2 + Migoku!C2 + 'North Ayre'!C2 + Oscairia!C2 + Oyreain!C2 + 'Pha Hii'!C2 + 'Pruim Fijan'!C2 + 'Prystr Hii'!C2 + 'Ruylku'!C2 + Sanagara!C2 + Shinam!C2 + Stinebar!C2 + Suenan!C2 + Taval!C2 + Ucrua!C2 + Vesozata!C2 + 'Welenu Fana'!C2 + 'Western Migoku'!C2 -> 1.3890988e+09 | BF2: =((BE2-BE3)/BE3) -> 0.0071160083 | BG2: =SUM(BE2/C2) -> 0.20281243 | BN2: =SUM(BO2+250) -> 2015 | BO2: 1765 | BP2: =Andsaudare!C2 + Aplasia!C2 + Astye!C2 + 'Crila Republic'!C2 + 'Elja and Munusia'!C2 + Hiwush!C2 + Iainoa!C2 + Isari!C2 + Isuibul!C2 + Maalle!C2 + Mendereide!C2 + Nia!C2 + 'Niretui and Anulan'!C2 + Ohtina!C2 + Prstreula!C2 + 'Rethern'!C2 + 'Rkmepuia'!C2 + Tvecoca!C2 + Umarcia!C2 + 'United Delet'!C2 + Veelmit!C2 + Walporein!C2 + Yutnitu!C2 -> 2.760672e+08 | BQ2: =((BP2-BP3)/BP3) -> 0.011087359 | BR2: =SUM(BP2/C2) -> 0.040306605 | BY2: =SUM(BZ2+250) -> 2015 | BZ2: 1765 | CA2: =Ahokini!C2 + Anymna!C2 + Ashain!C2 + Baluyde!C2 + Desaki!C2 + Erkizil!C2 + 'Far Lands'!C2 + Finae!C2 + Hyelen!C2 + Iareva!C2 + Letan!C2 + 'Mesjan Hyaa'!C2 + Myla!C2 + 'Nheyes Si'!C2 + Onphello!C2 + Quidic!C2 + Shomjind!C2 + 'United Mihili'!C2 + Verste!C2 + Volver!C2 + Wundry!C2 + Yihnurda!C2 + Zhanshe!C2 + Ztesh!C2 -> 1.1689143e+09 | CB2: =((CA2-CA3)/CA3) -> 0.011908833 | CC2: =SUM(CA2/C2) -> 0.17066484
A3: =SUM(B3+250) -> 2014 | B3: 1764 | C3: =Acetoa!C3 + Acrana!C3 + Aetintio!C3 + Ahokini!C3 + Amcha!C3 + Andsaudare!C3 + Anymna!C3 + Aplasia!C3 + Arbiya!C3 + 'Areoix Lie'!C3 + Ashain!C3 + Astye!C3 + Baluyde!C3 + Byllu!C3 + 'Candenat'!C3 + 'Canldives'!C3 + 'Chaenia'!C3 + 'Cloja'!C3 + 'Crila Republic'!C3 + 'Cruthi Anoso'!C3 + 'Curata'!C3 + Dahe!C3 + Danocia!C3 + Darewa!C3 + Desaki!C3 + Deschon!C3 + 'Disal Nila'!C3 + 'Dual Cenryia'!C3 + Ealdorii!C3 + Easuhura!C3 + Eldavpir!C3 + Eldjo!C3 + 'Elja and Munusia'!C3 + Emara!C3 + Enina!C3 + Eparia!C3 + Erkizil!C3 + Estijan!C3 + Etirha!C3 + Etretes!C3 + Exilium!C3 + 'Far Lands'!C3 + 'Feio Lie'!C3 + Fermori!C3 + Finae!C3 + Fincen!C3 + 'Fire Coast'!C3 + Gaeiya!C3 + Galca!C3 + Genaire!C3 + Grazail!C3 + Guise!C3 + Haiza!C3 + Heiso!C3 + Hiwush!C3 + Hkuqo!C3 + Hyelen!C3 + Iainoa!C3 + Iareva!C3 + Ihner!C3 + Ikzen!C3 + Ilicuhe!C3 + Inania!C3 + Inrea!C3 + Iquir!C3 + Isari!C3 + Isnti!C3 + Isuibul!C3 + Jathua!C3 + Jau!C3 + Jshain!C3 + Kaastini!C3 + Koruch!C3 + Kusierna!C3 + Laselteh!C3 + Lasri!C3 + Letan!C3 + Lieri!C3 + Lycroa!C3 + Lydroa!C3 + Maalle!C3 + Mendereide!C3 + 'Merela Sta'!C3 + 'Mesjan Hyaa'!C3 + Metndria!C3 + Migoku!C3 + Myla!C3 + 'New Kizura'!C3 + 'New Misos'!C3 + 'Nheyes Si'!C3 + Nia!C3 + 'Niretui and Anulan'!C3 + 'Niul Spijan'!C3 + 'North Ayre'!C3 + Ocaun!C3 + Ohtina!C3 + Onphello!C3 + Oscairia!C3 + Othya!C3 + Otiiric!C3 + Oyreain!C3 + Ozinia!C3 + Palina!C3 + Peka!C3 + Pelan!C3 + Pelines!C3 + Pelugrotoa!C3 + 'Pha Hii'!C3 + Phuris!C3 + Praesyu!C3 + Prstreula!C3 + 'Pruim Fijan'!C3 + 'Prystr Hii'!C3 + Quidic!C3 + 'Raledria'!C3 + 'Reerica'!C3 + 'Rethern'!C3 + 'Rijan bu'!C3 + 'Rinew'!C3 + 'Rkmepuia'!C3 + 'Rtesania'!C3 + 'Ruylku'!C3 + Saa!C3 + Sadain!C3 + Sanagara!C3 + Sattle!C3 + Selaja!C3 + Seytinemas!C3 + Shinam!C3 + Shomjind!C3 + Siana!C3 + Sivoso!C3 + Slyiaduun!C3 + Stinebar!C3 + Suenan!C3 + Sunsokua!C3 + Taing!C3 + Taniduna!C3 + Taoisia!C3 + Taval!C3 + Terressin!C3 + Tomscilus!C3 + Tonder!C3 + Trevilla!C3 + Trian!C3 + Tvecoca!C3 + Ucrua!C3 + Ukhdari!C3 + Umarcia!C3 + Umendel!C3 + 'United Delet'!C3 + 'United Mihili'!C3 + Urbiqu!C3 + Uularin!C3 + Vayvele!C3 + Veelmit!C3 + Verste!C3 + Verusa!C3 + Vesozata!C3 + Viussi!C3 + Volver!C3 + Walporein!C3 + 'Welenu Fana'!C3 + 'Western Migoku'!C3 + Wundry!C3 + Yaxuto!C3 + Yihnurda!C3 + Yoprioq!C3 + Yutnitu!C3 + Zenashan!C3 + Zhanshe!C3 + Ztesh!C3 -> 6.783743e+09 | D3: =((C3-C4)/C4) -> 0.0098200828 | K3: =SUM(L3+250) -> 2014 | L3: 1764 | M3: ='Areoix Lie'!C3 + Pelines!C3 + Terressin!C3 + Taniduna!C3 + Iquir!C3 + Deschon!C3 + Othya!C3 + Eldavpir!C3 + 'Candenat'!C3 + Jau!C3 + Viussi!C3 + Jathua!C3 + Jshain!C3 + Acetoa!C3 + Sattle!C3 + 'Reerica'!C3 + 'Feio Lie'!C3 + Umendel!C3 + 'Fire Coast'!C3 + Yoprioq!C3 + 'Rijan bu'!C3 + Saa!C3 + 'Rinew'!C3 + Enina!C3 + Trevilla!C3 -> 1.0574015e+09 | N3: =((M3-M4)/M4) -> 0.012193103 | O3: =SUM(M3/C3) -> 0.15587287 | V3: =SUM(W3+250) -> 2014 | W3: 1764 | X3: =Aetintio!C3 + Arbiya!C3 + 'Curata'!C3 + 'Disal Nila'!C3 + Etirha!C3 + Fincen!C3 + Gaeiya!C3 + Genaire!C3 + Grazail!C3 + Guise!C3 + Laselteh!C3 + Lasri!C3 + Metndria!C3 + 'New Misos'!C3 + Peka!C3 + Pelan!C3 + Phuris!C3 + 'Raledria'!C3 + Slyiaduun!C3 + Tomscilus!C3 -> 5.3151204e+08 | Y3: =((X3-X4)/X4) -> 0.011528272 | Z3: =SUM(X3/C3) -> 0.078350852 | AG3: =SUM(AH3+250) -> 2014 | AH3: 1764 | AI3: =Acrana!C3 + Danocia!C3 + Darewa!C3 + Ealdorii!C3 + Easuhura!C3 + Eldjo!C3 + Emara!C3 + Estijan!C3 + Fermori!C3 + Ikzen!C3 + Ilicuhe!C3 + Koruch!C3 + Lycroa!C3 + Lydroa!C3 + 'Merela Sta'!C3 + 'New Kizura'!C3 + 'Niul Spijan'!C3 + Palina!C3 + Praesyu!C3 + Siana!C3 + Tonder!C3 + Ukhdari!C3 + Urbiqu!C3 + Uularin!C3 + Verusa!C3 + Yaxuto!C3 + Zenashan!C3 + Hkuqo!C3 -> 9.9307946e+08 | AJ3: =((AI3-AI4)/AI4) -> 0.0065056736 | AK3: =SUM(AI3/C3) -> 0.14639108 | AR3: =SUM(AS3+250) -> 2014 | AS3: 1764 | AT3: =Amcha!C3 + Byllu!C3 + 'Chaenia'!C3 + 'Cruthi Anoso'!C3 + 'Dual Cenryia'!C3 + Exilium!C3 + Galca!C3 + Inania!C3 + Inrea!C3 + Isnti!C3 + Lieri!C3 + Ocaun!C3 + Otiiric!C3 + Ozinia!C3 + Pelugrotoa!C3 + 'Rtesania'!C3 + Sadain!C3 + Selaja!C3 + Seytinemas!C3 + Sivoso!C3 + Sunsokua!C3 + Taing!C3 + Taoisia!C3 + Trian!C3 + Vayvele!C3 -> 1.37387e+09 | AU3: =((AT3-AT4)/AT4) -> 0.0099515274 | AV3: =SUM(AT3/C3) -> 0.20252389 | BC3: =SUM(BD3+250) -> 2014 | BD3: 1764 | BE3: ='Canldives'!C3 + 'Cloja'!C3 + Dahe!C3 + Eparia!C3 + Etretes!C3 + Haiza!C3 + Ihner!C3 + Kaastini!C3 + Kusierna!C3 + Migoku!C3 + 'North Ayre'!C3 + Oscairia!C3 + Oyreain!C3 + 'Pha Hii'!C3 + 'Pruim Fijan'!C3 + 'Prystr Hii'!C3 + 'Ruylku'!C3 + Sanagara!C3 + Shinam!C3 + Stinebar!C3 + Suenan!C3 + Taval!C3 + Ucrua!C3 + Vesozata!C3 + 'Welenu Fana'!C3 + 'Western Migoku'!C3 -> 1.3792838e+09 | BF3: =((BE3-BE4)/BE4) -> 0.007000883 | BG3: =SUM(BE3/C3) -> 0.20332195 | BN3: =SUM(BO3+250) -> 2014 | BO3: 1764 | BP3: =Andsaudare!C3 + Aplasia!C3 + Astye!C3 + 'Crila Republic'!C3 + 'Elja and Munusia'!C3 + Hiwush!C3 + Iainoa!C3 + Isari!C3 + Isuibul!C3 + Maalle!C3 + Mendereide!C3 + Nia!C3 + 'Niretui and Anulan'!C3 + Ohtina!C3 + Prstreula!C3 + 'Rethern'!C3 + 'Rkmepuia'!C3 + Tvecoca!C3 + Umarcia!C3 + 'United Delet'!C3 + Veelmit!C3 + Walporein!C3 + Yutnitu!C3 -> 2.7303991e+08 | BQ3: =((BP3-BP4)/BP4) -> 0.011549713 | BR3: =SUM(BP3/C3) -> 0.040249152 | BY3: =SUM(BZ3+250) -> 2014 | BZ3: 1764 | CA3: =Ahokini!C3 + Anymna!C3 + Ashain!C3 + Baluyde!C3 + Desaki!C3 + Erkizil!C3 + 'Far Lands'!C3 + Finae!C3 + Hyelen!C3 + Iareva!C3 + Letan!C3 + 'Mesjan Hyaa'!C3 + Myla!C3 + 'Nheyes Si'!C3 + Onphello!C3 + Quidic!C3 + Shomjind!C3 + 'United Mihili'!C3 + Verste!C3 + Volver!C3 + Wundry!C3 + Yihnurda!C3 + Zhanshe!C3 + Ztesh!C3 -> 1.1551577e+09 | CB3: =((CA3-CA4)/CA4) -> 0.012526438 | CC3: =SUM(CA3/C3) -> 0.17028323
A4: =SUM(B4+250) -> 2013 | B4: 1763 | C4: =Acetoa!C4 + Acrana!C4 + Aetintio!C4 + Ahokini!C4 + Amcha!C4 + Andsaudare!C4 + Anymna!C4 + Aplasia!C4 + Arbiya!C4 + 'Areoix Lie'!C4 + Ashain!C4 + Astye!C4 + Baluyde!C4 + Byllu!C4 + 'Candenat'!C4 + 'Canldives'!C4 + 'Chaenia'!C4 + 'Cloja'!C4 + 'Crila Republic'!C4 + 'Cruthi Anoso'!C4 + 'Curata'!C4 + Dahe!C4 + Danocia!C4 + Darewa!C4 + Desaki!C4 + Deschon!C4 + 'Disal Nila'!C4 + 'Dual Cenryia'!C4 + Ealdorii!C4 + Easuhura!C4 + Eldavpir!C4 + Eldjo!C4 + 'Elja and Munusia'!C4 + Emara!C4 + Enina!C4 + Eparia!C4 + Erkizil!C4 + Estijan!C4 + Etirha!C4 + Etretes!C4 + Exilium!C4 + 'Far Lands'!C4 + 'Feio Lie'!C4 + Fermori!C4 + Finae!C4 + Fincen!C4 + 'Fire Coast'!C4 + Gaeiya!C4 + Galca!C4 + Genaire!C4 + Grazail!C4 + Guise!C4 + Haiza!C4 + Heiso!C4 + Hiwush!C4 + Hkuqo!C4 + Hyelen!C4 + Iainoa!C4 + Iareva!C4 + Ihner!C4 + Ikzen!C4 + Ilicuhe!C4 + Inania!C4 + Inrea!C4 + Iquir!C4 + Isari!C4 + Isnti!C4 + Isuibul!C4 + Jathua!C4 + Jau!C4 + Jshain!C4 + Kaastini!C4 + Koruch!C4 + Kusierna!C4 + Laselteh!C4 + Lasri!C4 + Letan!C4 + Lieri!C4 + Lycroa!C4 + Lydroa!C4 + Maalle!C4 + Mendereide!C4 + 'Merela Sta'!C4 + 'Mesjan Hyaa'!C4 + Metndria!C4 + Migoku!C4 + Myla!C4 + 'New Kizura'!C4 + 'New Misos'!C4 + 'Nheyes Si'!C4 + Nia!C4 + 'Niretui and Anulan'!C4 + 'Niul Spijan'!C4 + 'North Ayre'!C4 + Ocaun!C4 + Ohtina!C4 + Onphello!C4 + Oscairia!C4 + Othya!C4 + Otiiric!C4 + Oyreain!C4 + Ozinia!C4 + Palina!C4 + Peka!C4 + Pelan!C4 + Pelines!C4 + Pelugrotoa!C4 + 'Pha Hii'!C4 + Phuris!C4 + Praesyu!C4 + Prstreula!C4 + 'Pruim Fijan'!C4 + 'Prystr Hii'!C4 + Quidic!C4 + 'Raledria'!C4 + 'Reerica'!C4 + 'Rethern'!C4 + 'Rijan bu'!C4 + 'Rinew'!C4 + 'Rkmepuia'!C4 + 'Rtesania'!C4 + 'Ruylku'!C4 + Saa!C4 + Sadain!C4 + Sanagara!C4 + Sattle!C4 + Selaja!C4 + Seytinemas!C4 + Shinam!C4 + Shomjind!C4 + Siana!C4 + Sivoso!C4 + Slyiaduun!C4 + Stinebar!C4 + Suenan!C4 + Sunsokua!C4 + Taing!C4 + Taniduna!C4 + Taoisia!C4 + Taval!C4 + Terressin!C4 + Tomscilus!C4 + Tonder!C4 + Trevilla!C4 + Trian!C4 + Tvecoca!C4 + Ucrua!C4 + Ukhdari!C4 + Umarcia!C4 + Umendel!C4 + 'United Delet'!C4 + 'United Mihili'!C4 + Urbiqu!C4 + Uularin!C4 + Vayvele!C4 + Veelmit!C4 + Verste!C4 + Verusa!C4 + Vesozata!C4 + Viussi!C4 + Volver!C4 + Walporein!C4 + 'Welenu Fana'!C4 + 'Western Migoku'!C4 + Wundry!C4 + Yaxuto!C4 + Yihnurda!C4 + Yoprioq!C4 + Yutnitu!C4 + Zenashan!C4 + Zhanshe!C4 + Ztesh!C4 -> 6.7177739e+09 | D4: =((C4-C5)/C5) -> 0.0098609584 | K4: =SUM(L4+250) -> 2013 | L4: 1763 | M4: ='Areoix Lie'!C4 + Pelines!C4 + Terressin!C4 + Taniduna!C4 + Iquir!C4 + Deschon!C4 + Othya!C4 + Eldavpir!C4 + 'Candenat'!C4 + Jau!C4 + Viussi!C4 + Jathua!C4 + Jshain!C4 + Acetoa!C4 + Sattle!C4 + 'Reerica'!C4 + 'Feio Lie'!C4 + Umendel!C4 + 'Fire Coast'!C4 + Yoprioq!C4 + 'Rijan bu'!C4 + Saa!C4 + 'Rinew'!C4 + Enina!C4 + Trevilla!C4 -> 1.0446638e+09 | N4: =((M4-M5)/M5) -> 0.011587611 | O4: =SUM(M4/C4) -> 0.15550744 | V4: =SUM(W4+250) -> 2013 | W4: 1763 | X4: =Aetintio!C4 + Arbiya!C4 + 'Curata'!C4 + 'Disal Nila'!C4 + Etirha!C4 + Fincen!C4 + Gaeiya!C4 + Genaire!C4 + Grazail!C4 + Guise!C4 + Laselteh!C4 + Lasri!C4 + Metndria!C4 + 'New Misos'!C4 + Peka!C4 + Pelan!C4 + Phuris!C4 + 'Raledria'!C4 + Slyiaduun!C4 + Tomscilus!C4 -> 5.2545446e+08 | Y4: =((X4-X5)/X5) -> 0.012712502 | Z4: =SUM(X4/C4) -> 0.078218539 | AG4: =SUM(AH4+250) -> 2013 | AH4: 1763 | AI4: =Acrana!C4 + Danocia!C4 + Darewa!C4 + Ealdorii!C4 + Easuhura!C4 + Eldjo!C4 + Emara!C4 + Estijan!C4 + Fermori!C4 + Ikzen!C4 + Ilicuhe!C4 + Koruch!C4 + Lycroa!C4 + Lydroa!C4 + 'Merela Sta'!C4 + 'New Kizura'!C4 + 'Niul Spijan'!C4 + Palina!C4 + Praesyu!C4 + Siana!C4 + Tonder!C4 + Ukhdari!C4 + Urbiqu!C4 + Uularin!C4 + Verusa!C4 + Yaxuto!C4 + Zenashan!C4 + Hkuqo!C4 -> 9.8666057e+08 | AJ4: =((AI4-AI5)/AI5) -> 0.006512277 | AK4: =SUM(AI4/C4) -> 0.14687314 | AR4: =SUM(AS4+250) -> 2013 | AS4: 1763 | AT4: =Amcha!C4 + Byllu!C4 + 'Chaenia'!C4 + 'Cruthi Anoso'!C4 + 'Dual Cenryia'!C4 + Exilium!C4 + Galca!C4 + Inania!C4 + Inrea!C4 + Isnti!C4 + Lieri!C4 + Ocaun!C4 + Otiiric!C4 + Ozinia!C4 + Pelugrotoa!C4 + 'Rtesania'!C4 + Sadain!C4 + Selaja!C4 + Seytinemas!C4 + Sivoso!C4 + Sunsokua!C4 + Taing!C4 + Taoisia!C4 + Trian!C4 + Vayvele!C4 -> 1.3603326e+09 | AU4: =((AT4-AT5)/AT5) -> 0.0099131221 | AV4: =SUM(AT4/C4) -> 0.20249753 | BC4: =SUM(BD4+250) -> 2013 | BD4: 1763 | BE4: ='Canldives'!C4 + 'Cloja'!C4 + Dahe!C4 + Eparia!C4 + Etretes!C4 + Haiza!C4 + Ihner!C4 + Kaastini!C4 + Kusierna!C4 + Migoku!C4 + 'North Ayre'!C4 + Oscairia!C4 + Oyreain!C4 + 'Pha Hii'!C4 + 'Pruim Fijan'!C4 + 'Prystr Hii'!C4 + 'Ruylku'!C4 + Sanagara!C4 + Shinam!C4 + Stinebar!C4 + Suenan!C4 + Taval!C4 + Ucrua!C4 + Vesozata!C4 + 'Welenu Fana'!C4 + 'Western Migoku'!C4 -> 1.3696948e+09 | BF4: =((BE4-BE5)/BE5) -> 0.0067701805 | BG4: =SUM(BE4/C4) -> 0.20389117 | BN4: =SUM(BO4+250) -> 2013 | BO4: 1763 | BP4: =Andsaudare!C4 + Aplasia!C4 + Astye!C4 + 'Crila Republic'!C4 + 'Elja and Munusia'!C4 + Hiwush!C4 + Iainoa!C4 + Isari!C4 + Isuibul!C4 + Maalle!C4 + Mendereide!C4 + Nia!C4 + 'Niretui and Anulan'!C4 + Ohtina!C4 + Prstreula!C4 + 'Rethern'!C4 + 'Rkmepuia'!C4 + Tvecoca!C4 + Umarcia!C4 + 'United Delet'!C4 + Veelmit!C4 + Walporein!C4 + Yutnitu!C4 -> 2.6992238e+08 | BQ4: =((BP4-BP5)/BP5) -> 0.01183094 | BR4: =SUM(BP4/C4) -> 0.040180331 | BY4: =SUM(BZ4+250) -> 2013 | BZ4: 1763 | CA4: =Ahokini!C4 + Anymna!C4 + Ashain!C4 + Baluyde!C4 + Desaki!C4 + Erkizil!C4 + 'Far Lands'!C4 + Finae!C4 + Hyelen!C4 + Iareva!C4 + Letan!C4 + 'Mesjan Hyaa'!C4 + Myla!C4 + 'Nheyes Si'!C4 + Onphello!C4 + Quidic!C4 + Shomjind!C4 + 'United Mihili'!C4 + Verste!C4 + Volver!C4 + Wundry!C4 + Yihnurda!C4 + Zhanshe!C4 + Ztesh!C4 -> 1.1408667e+09 | CB4: =((CA4-CA5)/CA5) -> 0.013054492 | CC4: =SUM(CA4/C4) -> 0.16982809
A5: =SUM(B5+250) -> 2012 | B5: 1762 | C5: =Acetoa!C5 + Acrana!C5 + Aetintio!C5 + Ahokini!C5 + Amcha!C5 + Andsaudare!C5 + Anymna!C5 + Aplasia!C5 + Arbiya!C5 + 'Areoix Lie'!C5 + Ashain!C5 + Astye!C5 + Baluyde!C5 + Byllu!C5 + 'Candenat'!C5 + 'Canldives'!C5 + 'Chaenia'!C5 + 'Cloja'!C5 + 'Crila Republic'!C5 + 'Cruthi Anoso'!C5 + 'Curata'!C5 + Dahe!C5 + Danocia!C5 + Darewa!C5 + Desaki!C5 + Deschon!C5 + 'Disal Nila'!C5 + 'Dual Cenryia'!C5 + Ealdorii!C5 + Easuhura!C5 + Eldavpir!C5 + Eldjo!C5 + 'Elja and Munusia'!C5 + Emara!C5 + Enina!C5 + Eparia!C5 + Erkizil!C5 + Estijan!C5 + Etirha!C5 + Etretes!C5 + Exilium!C5 + 'Far Lands'!C5 + 'Feio Lie'!C5 + Fermori!C5 + Finae!C5 + Fincen!C5 + 'Fire Coast'!C5 + Gaeiya!C5 + Galca!C5 + Genaire!C5 + Grazail!C5 + Guise!C5 + Haiza!C5 + Heiso!C5 + Hiwush!C5 + Hkuqo!C5 + Hyelen!C5 + Iainoa!C5 + Iareva!C5 + Ihner!C5 + Ikzen!C5 + Ilicuhe!C5 + Inania!C5 + Inrea!C5 + Iquir!C5 + Isari!C5 + Isnti!C5 + Isuibul!C5 + Jathua!C5 + Jau!C5 + Jshain!C5 + Kaastini!C5 + Koruch!C5 + Kusierna!C5 + Laselteh!C5 + Lasri!C5 + Letan!C5 + Lieri!C5 + Lycroa!C5 + Lydroa!C5 + Maalle!C5 + Mendereide!C5 + 'Merela Sta'!C5 + 'Mesjan Hyaa'!C5 + Metndria!C5 + Migoku!C5 + Myla!C5 + 'New Kizura'!C5 + 'New Misos'!C5 + 'Nheyes Si'!C5 + Nia!C5 + 'Niretui and Anulan'!C5 + 'Niul Spijan'!C5 + 'North Ayre'!C5 + Ocaun!C5 + Ohtina!C5 + Onphello!C5 + Oscairia!C5 + Othya!C5 + Otiiric!C5 + Oyreain!C5 + Ozinia!C5 + Palina!C5 + Peka!C5 + Pelan!C5 + Pelines!C5 + Pelugrotoa!C5 + 'Pha Hii'!C5 + Phuris!C5 + Praesyu!C5 + Prstreula!C5 + 'Pruim Fijan'!C5 + 'Prystr Hii'!C5 + Quidic!C5 + 'Raledria'!C5 + 'Reerica'!C5 + 'Rethern'!C5 + 'Rijan bu'!C5 + 'Rinew'!C5 + 'Rkmepuia'!C5 + 'Rtesania'!C5 + 'Ruylku'!C5 + Saa!C5 + Sadain!C5 + Sanagara!C5 + Sattle!C5 + Selaja!C5 + Seytinemas!C5 + Shinam!C5 + Shomjind!C5 + Siana!C5 + Sivoso!C5 + Slyiaduun!C5 + Stinebar!C5 + Suenan!C5 + Sunsokua!C5 + Taing!C5 + Taniduna!C5 + Taoisia!C5 + Taval!C5 + Terressin!C5 + Tomscilus!C5 + Tonder!C5 + Trevilla!C5 + Trian!C5 + Tvecoca!C5 + Ucrua!C5 + Ukhdari!C5 + Umarcia!C5 + Umendel!C5 + 'United Delet'!C5 + 'United Mihili'!C5 + Urbiqu!C5 + Uularin!C5 + Vayvele!C5 + Veelmit!C5 + Verste!C5 + Verusa!C5 + Vesozata!C5 + Viussi!C5 + Volver!C5 + Walporein!C5 + 'Welenu Fana'!C5 + 'Western Migoku'!C5 + Wundry!C5 + Yaxuto!C5 + Yihnurda!C5 + Yoprioq!C5 + Yutnitu!C5 + Zenashan!C5 + Zhanshe!C5 + Ztesh!C5 -> 6.6521771e+09 | D5: =((C5-C6)/C6) -> 0.01007584 | K5: =SUM(L5+250) -> 2012 | L5: 1762 | M5: ='Areoix Lie'!C5 + Pelines!C5 + Terressin!C5 + Taniduna!C5 + Iquir!C5 + Deschon!C5 + Othya!C5 + Eldavpir!C5 + 'Candenat'!C5 + Jau!C5 + Viussi!C5 + Jathua!C5 + Jshain!C5 + Acetoa!C5 + Sattle!C5 + 'Reerica'!C5 + 'Feio Lie'!C5 + Umendel!C5 + 'Fire Coast'!C5 + Yoprioq!C5 + 'Rijan bu'!C5 + Saa!C5 + 'Rinew'!C5 + Enina!C5 + Trevilla!C5 -> 1.0326973e+09 | N5: =((M5-M6)/M6) -> 0.011045252 | O5: =SUM(M5/C5) -> 0.15524201 | V5: =SUM(W5+250) -> 2012 | W5: 1762 | X5: =Aetintio!C5 + Arbiya!C5 + 'Curata'!C5 + 'Disal Nila'!C5 + Etirha!C5 + Fincen!C5 + Gaeiya!C5 + Genaire!C5 + Grazail!C5 + Guise!C5 + Laselteh!C5 + Lasri!C5 + Metndria!C5 + 'New Misos'!C5 + Peka!C5 + Pelan!C5 + Phuris!C5 + 'Raledria'!C5 + Slyiaduun!C5 + Tomscilus!C5 -> 5.1885847e+08 | Y5: =((X5-X6)/X6) -> 0.013080513 | Z5: =SUM(X5/C5) -> 0.077998295 | AG5: =SUM(AH5+250) -> 2012 | AH5: 1762 | AI5: =Acrana!C5 + Danocia!C5 + Darewa!C5 + Ealdorii!C5 + Easuhura!C5 + Eldjo!C5 + Emara!C5 + Estijan!C5 + Fermori!C5 + Ikzen!C5 + Ilicuhe!C5 + Koruch!C5 + Lycroa!C5 + Lydroa!C5 + 'Merela Sta'!C5 + 'New Kizura'!C5 + 'Niul Spijan'!C5 + Palina!C5 + Praesyu!C5 + Siana!C5 + Tonder!C5 + Ukhdari!C5 + Urbiqu!C5 + Uularin!C5 + Verusa!C5 + Yaxuto!C5 + Zenashan!C5 + Hkuqo!C5 -> 9.8027674e+08 | AJ5: =((AI5-AI6)/AI6) -> 0.006759365 | AK5: =SUM(AI5/C5) -> 0.14736179 | AR5: =SUM(AS5+250) -> 2012 | AS5: 1762 | AT5: =Amcha!C5 + Byllu!C5 + 'Chaenia'!C5 + 'Cruthi Anoso'!C5 + 'Dual Cenryia'!C5 + Exilium!C5 + Galca!C5 + Inania!C5 + Inrea!C5 + Isnti!C5 + Lieri!C5 + Ocaun!C5 + Otiiric!C5 + Ozinia!C5 + Pelugrotoa!C5 + 'Rtesania'!C5 + Sadain!C5 + Selaja!C5 + Seytinemas!C5 + Sivoso!C5 + Sunsokua!C5 + Taing!C5 + Taoisia!C5 + Trian!C5 + Vayvele!C5 -> 1.3469798e+09 | AU5: =((AT5-AT6)/AT6) -> 0.010133468 | AV5: =SUM(AT5/C5) -> 0.20248707 | BC5: =SUM(BD5+250) -> 2012 | BD5: 1762 | BE5: ='Canldives'!C5 + 'Cloja'!C5 + Dahe!C5 + Eparia!C5 + Etretes!C5 + Haiza!C5 + Ihner!C5 + Kaastini!C5 + Kusierna!C5 + Migoku!C5 + 'North Ayre'!C5 + Oscairia!C5 + Oyreain!C5 + 'Pha Hii'!C5 + 'Pruim Fijan'!C5 + 'Prystr Hii'!C5 + 'Ruylku'!C5 + Sanagara!C5 + Shinam!C5 + Stinebar!C5 + Suenan!C5 + Taval!C5 + Ucrua!C5 + Vesozata!C5 + 'Welenu Fana'!C5 + 'Western Migoku'!C5 -> 1.360484e+09 | BF5: =((BE5-BE6)/BE6) -> 0.0071313151 | BG5: =SUM(BE5/C5) -> 0.20451711 | BN5: =SUM(BO5+250) -> 2012 | BO5: 1762 | BP5: =Andsaudare!C5 + Aplasia!C5 + Astye!C5 + 'Crila Republic'!C5 + 'Elja and Munusia'!C5 + Hiwush!C5 + Iainoa!C5 + Isari!C5 + Isuibul!C5 + Maalle!C5 + Mendereide!C5 + Nia!C5 + 'Niretui and Anulan'!C5 + Ohtina!C5 + Prstreula!C5 + 'Rethern'!C5 + 'Rkmepuia'!C5 + Tvecoca!C5 + Umarcia!C5 + 'United Delet'!C5 + Veelmit!C5 + Walporein!C5 + Yutnitu!C5 -> 2.6676628e+08 | BQ5: =((BP5-BP6)/BP6) -> 0.012526868 | BR5: =SUM(BP5/C5) -> 0.040102102 | BY5: =SUM(BZ5+250) -> 2012 | BZ5: 1762 | CA5: =Ahokini!C5 + Anymna!C5 + Ashain!C5 + Baluyde!C5 + Desaki!C5 + Erkizil!C5 + 'Far Lands'!C5 + Finae!C5 + Hyelen!C5 + Iareva!C5 + Letan!C5 + 'Mesjan Hyaa'!C5 + Myla!C5 + 'Nheyes Si'!C5 + Onphello!C5 + Quidic!C5 + Shomjind!C5 + 'United Mihili'!C5 + Verste!C5 + Volver!C5 + Wundry!C5 + Yihnurda!C5 + Zhanshe!C5 + Ztesh!C5 -> 1.1261652e+09 | CB5: =((CA5-CA6)/CA6) -> 0.013596237 | CC5: =SUM(CA5/C5) -> 0.16929272
A6: =SUM(B6+250) -> 2011 | B6: 1761 | C6: =Acetoa!C6 + Acrana!C6 + Aetintio!C6 + Ahokini!C6 + Amcha!C6 + Andsaudare!C6 + Anymna!C6 + Aplasia!C6 + Arbiya!C6 + 'Areoix Lie'!C6 + Ashain!C6 + Astye!C6 + Baluyde!C6 + Byllu!C6 + 'Candenat'!C6 + 'Canldives'!C6 + 'Chaenia'!C6 + 'Cloja'!C6 + 'Crila Republic'!C6 + 'Cruthi Anoso'!C6 + 'Curata'!C6 + Dahe!C6 + Danocia!C6 + Darewa!C6 + Desaki!C6 + Deschon!C6 + 'Disal Nila'!C6 + 'Dual Cenryia'!C6 + Ealdorii!C6 + Easuhura!C6 + Eldavpir!C6 + Eldjo!C6 + 'Elja and Munusia'!C6 + Emara!C6 + Enina!C6 + Eparia!C6 + Erkizil!C6 + Estijan!C6 + Etirha!C6 + Etretes!C6 + Exilium!C6 + 'Far Lands'!C6 + 'Feio Lie'!C6 + Fermori!C6 + Finae!C6 + Fincen!C6 + 'Fire Coast'!C6 + Gaeiya!C6 + Galca!C6 + Genaire!C6 + Grazail!C6 + Guise!C6 + Haiza!C6 + Heiso!C6 + Hiwush!C6 + Hkuqo!C6 + Hyelen!C6 + Iainoa!C6 + Iareva!C6 + Ihner!C6 + Ikzen!C6 + Ilicuhe!C6 + Inania!C6 + Inrea!C6 + Iquir!C6 + Isari!C6 + Isnti!C6 + Isuibul!C6 + Jathua!C6 + Jau!C6 + Jshain!C6 + Kaastini!C6 + Koruch!C6 + Kusierna!C6 + Laselteh!C6 + Lasri!C6 + Letan!C6 + Lieri!C6 + Lycroa!C6 + Lydroa!C6 + Maalle!C6 + Mendereide!C6 + 'Merela Sta'!C6 + 'Mesjan Hyaa'!C6 + Metndria!C6 + Migoku!C6 + Myla!C6 + 'New Kizura'!C6 + 'New Misos'!C6 + 'Nheyes Si'!C6 + Nia!C6 + 'Niretui and Anulan'!C6 + 'Niul Spijan'!C6 + 'North Ayre'!C6 + Ocaun!C6 + Ohtina!C6 + Onphello!C6 + Oscairia!C6 + Othya!C6 + Otiiric!C6 + Oyreain!C6 + Ozinia!C6 + Palina!C6 + Peka!C6 + Pelan!C6 + Pelines!C6 + Pelugrotoa!C6 + 'Pha Hii'!C6 + Phuris!C6 + Praesyu!C6 + Prstreula!C6 + 'Pruim Fijan'!C6 + 'Prystr Hii'!C6 + Quidic!C6 + 'Raledria'!C6 + 'Reerica'!C6 + 'Rethern'!C6 + 'Rijan bu'!C6 + 'Rinew'!C6 + 'Rkmepuia'!C6 + 'Rtesania'!C6 + 'Ruylku'!C6 + Saa!C6 + Sadain!C6 + Sanagara!C6 + Sattle!C6 + Selaja!C6 + Seytinemas!C6 + Shinam!C6 + Shomjind!C6 + Siana!C6 + Sivoso!C6 + Slyiaduun!C6 + Stinebar!C6 + Suenan!C6 + Sunsokua!C6 + Taing!C6 + Taniduna!C6 + Taoisia!C6 + Taval!C6 + Terressin!C6 + Tomscilus!C6 + Tonder!C6 + Trevilla!C6 + Trian!C6 + Tvecoca!C6 + Ucrua!C6 + Ukhdari!C6 + Umarcia!C6 + Umendel!C6 + 'United Delet'!C6 + 'United Mihili'!C6 + Urbiqu!C6 + Uularin!C6 + Vayvele!C6 + Veelmit!C6 + Verste!C6 + Verusa!C6 + Vesozata!C6 + Viussi!C6 + Volver!C6 + Walporein!C6 + 'Welenu Fana'!C6 + 'Western Migoku'!C6 + Wundry!C6 + Yaxuto!C6 + Yihnurda!C6 + Yoprioq!C6 + Yutnitu!C6 + Zenashan!C6 + Zhanshe!C6 + Ztesh!C6 -> 6.5858194e+09 | D6: =((C6-C7)/C7) -> 0.010086267 | K6: =SUM(L6+250) -> 2011 | L6: 1761 | M6: ='Areoix Lie'!C6 + Pelines!C6 + Terressin!C6 + Taniduna!C6 + Iquir!C6 + Deschon!C6 + Othya!C6 + Eldavpir!C6 + 'Candenat'!C6 + Jau!C6 + Viussi!C6 + Jathua!C6 + Jshain!C6 + Acetoa!C6 + Sattle!C6 + 'Reerica'!C6 + 'Feio Lie'!C6 + Umendel!C6 + 'Fire Coast'!C6 + Yoprioq!C6 + 'Rijan bu'!C6 + Saa!C6 + 'Rinew'!C6 + Enina!C6 + Trevilla!C6 -> 1.0214155e+09 | N6: =((M6-M7)/M7) -> 0.01188251 | O6: =SUM(M6/C6) -> 0.15509316 | V6: =SUM(W6+250) -> 2011 | W6: 1761 | X6: =Aetintio!C6 + Arbiya!C6 + 'Curata'!C6 + 'Disal Nila'!C6 + Etirha!C6 + Fincen!C6 + Gaeiya!C6 + Genaire!C6 + Grazail!C6 + Guise!C6 + Laselteh!C6 + Lasri!C6 + Metndria!C6 + 'New Misos'!C6 + Peka!C6 + Pelan!C6 + Phuris!C6 + 'Raledria'!C6 + Slyiaduun!C6 + Tomscilus!C6 -> 5.1215917e+08 | Y6: =((X6-X7)/X7) -> 0.011055656 | Z6: =SUM(X6/C6) -> 0.077766962 | AG6: =SUM(AH6+250) -> 2011 | AH6: 1761 | AI6: =Acrana!C6 + Danocia!C6 + Darewa!C6 + Ealdorii!C6 + Easuhura!C6 + Eldjo!C6 + Emara!C6 + Estijan!C6 + Fermori!C6 + Ikzen!C6 + Ilicuhe!C6 + Koruch!C6 + Lycroa!C6 + Lydroa!C6 + 'Merela Sta'!C6 + 'New Kizura'!C6 + 'Niul Spijan'!C6 + Palina!C6 + Praesyu!C6 + Siana!C6 + Tonder!C6 + Ukhdari!C6 + Urbiqu!C6 + Uularin!C6 + Verusa!C6 + Yaxuto!C6 + Zenashan!C6 + Hkuqo!C6 -> 9.7369518e+08 | AJ6: =((AI6-AI7)/AI7) -> 0.0067869546 | AK6: =SUM(AI6/C6) -> 0.14784723 | AR6: =SUM(AS6+250) -> 2011 | AS6: 1761 | AT6: =Amcha!C6 + Byllu!C6 + 'Chaenia'!C6 + 'Cruthi Anoso'!C6 + 'Dual Cenryia'!C6 + Exilium!C6 + Galca!C6 + Inania!C6 + Inrea!C6 + Isnti!C6 + Lieri!C6 + Ocaun!C6 + Otiiric!C6 + Ozinia!C6 + Pelugrotoa!C6 + 'Rtesania'!C6 + Sadain!C6 + Selaja!C6 + Seytinemas!C6 + Sivoso!C6 + Sunsokua!C6 + Taing!C6 + Taoisia!C6 + Trian!C6 + Vayvele!C6 -> 1.3334672e+09 | AU6: =((AT6-AT7)/AT7) -> 0.0098042195 | AV6: =SUM(AT6/C6) -> 0.20247552 | BC6: =SUM(BD6+250) -> 2011 | BD6: 1761 | BE6: ='Canldives'!C6 + 'Cloja'!C6 + Dahe!C6 + Eparia!C6 + Etretes!C6 + Haiza!C6 + Ihner!C6 + Kaastini!C6 + Kusierna!C6 + Migoku!C6 + 'North Ayre'!C6 + Oscairia!C6 + Oyreain!C6 + 'Pha Hii'!C6 + 'Pruim Fijan'!C6 + 'Prystr Hii'!C6 + 'Ruylku'!C6 + Sanagara!C6 + Shinam!C6 + Stinebar!C6 + Suenan!C6 + Taval!C6 + Ucrua!C6 + Vesozata!C6 + 'Welenu Fana'!C6 + 'Western Migoku'!C6 -> 1.3508507e+09 | BF6: =((BE6-BE7)/BE7) -> 0.0070703532 | BG6: =SUM(BE6/C6) -> 0.20511505 | BN6: =SUM(BO6+250) -> 2011 | BO6: 1761 | BP6: =Andsaudare!C6 + Aplasia!C6 + Astye!C6 + 'Crila Republic'!C6 + 'Elja and Munusia'!C6 + Hiwush!C6 + Iainoa!C6 + Isari!C6 + Isuibul!C6 + Maalle!C6 + Mendereide!C6 + Nia!C6 + 'Niretui and Anulan'!C6 + Ohtina!C6 + Prstreula!C6 + 'Rethern'!C6 + 'Rkmepuia'!C6 + Tvecoca!C6 + Umarcia!C6 + 'United Delet'!C6 + Veelmit!C6 + Walporein!C6 + Yutnitu!C6 -> 2.6346588e+08 | BQ6: =((BP6-BP7)/BP7) -> 0.013633237 | BR6: =SUM(BP6/C6) -> 0.040005027 | BY6: =SUM(BZ6+250) -> 2011 | BZ6: 1761 | CA6: =Ahokini!C6 + Anymna!C6 + Ashain!C6 + Baluyde!C6 + Desaki!C6 + Erkizil!C6 + 'Far Lands'!C6 + Finae!C6 + Hyelen!C6 + Iareva!C6 + Letan!C6 + 'Mesjan Hyaa'!C6 + Myla!C6 + 'Nheyes Si'!C6 + Onphello!C6 + Quidic!C6 + Shomjind!C6 + 'United Mihili'!C6 + Verste!C6 + Volver!C6 + Wundry!C6 + Yihnurda!C6 + Zhanshe!C6 + Ztesh!C6 -> 1.111059e+09 | CB6: =((CA6-CA7)/CA7) -> 0.014004264 | CC6: =SUM(CA6/C6) -> 0.16870474
A7: =SUM(B7+250) -> 2010 | B7: 1760 | C7: =Acetoa!C7 + Acrana!C7 + Aetintio!C7 + Ahokini!C7 + Amcha!C7 + Andsaudare!C7 + Anymna!C7 + Aplasia!C7 + Arbiya!C7 + 'Areoix Lie'!C7 + Ashain!C7 + Astye!C7 + Baluyde!C7 + Byllu!C7 + 'Candenat'!C7 + 'Canldives'!C7 + 'Chaenia'!C7 + 'Cloja'!C7 + 'Crila Republic'!C7 + 'Cruthi Anoso'!C7 + 'Curata'!C7 + Dahe!C7 + Danocia!C7 + Darewa!C7 + Desaki!C7 + Deschon!C7 + 'Disal Nila'!C7 + 'Dual Cenryia'!C7 + Ealdorii!C7 + Easuhura!C7 + Eldavpir!C7 + Eldjo!C7 + 'Elja and Munusia'!C7 + Emara!C7 + Enina!C7 + Eparia!C7 + Erkizil!C7 + Estijan!C7 + Etirha!C7 + Etretes!C7 + Exilium!C7 + 'Far Lands'!C7 + 'Feio Lie'!C7 + Fermori!C7 + Finae!C7 + Fincen!C7 + 'Fire Coast'!C7 + Gaeiya!C7 + Galca!C7 + Genaire!C7 + Grazail!C7 + Guise!C7 + Haiza!C7 + Heiso!C7 + Hiwush!C7 + Hkuqo!C7 + Hyelen!C7 + Iainoa!C7 + Iareva!C7 + Ihner!C7 + Ikzen!C7 + Ilicuhe!C7 + Inania!C7 + Inrea!C7 + Iquir!C7 + Isari!C7 + Isnti!C7 + Isuibul!C7 + Jathua!C7 + Jau!C7 + Jshain!C7 + Kaastini!C7 + Koruch!C7 + Kusierna!C7 + Laselteh!C7 + Lasri!C7 + Letan!C7 + Lieri!C7 + Lycroa!C7 + Lydroa!C7 + Maalle!C7 + Mendereide!C7 + 'Merela Sta'!C7 + 'Mesjan Hyaa'!C7 + Metndria!C7 + Migoku!C7 + Myla!C7 + 'New Kizura'!C7 + 'New Misos'!C7 + 'Nheyes Si'!C7 + Nia!C7 + 'Niretui and Anulan'!C7 + 'Niul Spijan'!C7 + 'North Ayre'!C7 + Ocaun!C7 + Ohtina!C7 + Onphello!C7 + Oscairia!C7 + Othya!C7 + Otiiric!C7 + Oyreain!C7 + Ozinia!C7 + Palina!C7 + Peka!C7 + Pelan!C7 + Pelines!C7 + Pelugrotoa!C7 + 'Pha Hii'!C7 + Phuris!C7 + Praesyu!C7 + Prstreula!C7 + 'Pruim Fijan'!C7 + 'Prystr Hii'!C7 + Quidic!C7 + 'Raledria'!C7 + 'Reerica'!C7 + 'Rethern'!C7 + 'Rijan bu'!C7 + 'Rinew'!C7 + 'Rkmepuia'!C7 + 'Rtesania'!C7 + 'Ruylku'!C7 + Saa!C7 + Sadain!C7 + Sanagara!C7 + Sattle!C7 + Selaja!C7 + Seytinemas!C7 + Shinam!C7 + Shomjind!C7 + Siana!C7 + Sivoso!C7 + Slyiaduun!C7 + Stinebar!C7 + Suenan!C7 + Sunsokua!C7 + Taing!C7 + Taniduna!C7 + Taoisia!C7 + Taval!C7 + Terressin!C7 + Tomscilus!C7 + Tonder!C7 + Trevilla!C7 + Trian!C7 + Tvecoca!C7 + Ucrua!C7 + Ukhdari!C7 + Umarcia!C7 + Umendel!C7 + 'United Delet'!C7 + 'United Mihili'!C7 + Urbiqu!C7 + Uularin!C7 + Vayvele!C7 + Veelmit!C7 + Verste!C7 + Verusa!C7 + Vesozata!C7 + Viussi!C7 + Volver!C7 + Walporein!C7 + 'Welenu Fana'!C7 + 'Western Migoku'!C7 + Wundry!C7 + Yaxuto!C7 + Yihnurda!C7 + Yoprioq!C7 + Yutnitu!C7 + Zenashan!C7 + Zhanshe!C7 + Ztesh!C7 -> 6.5200564e+09 | D7: =((C7-C8)/C8) -> 0.01041509 | K7: =SUM(L7+250) -> 2010 | L7: 1760 | M7: ='Areoix Lie'!C7 + Pelines!C7 + Terressin!C7 + Taniduna!C7 + Iquir!C7 + Deschon!C7 + Othya!C7 + Eldavpir!C7 + 'Candenat'!C7 + Jau!C7 + Viussi!C7 + Jathua!C7 + Jshain!C7 + Acetoa!C7 + Sattle!C7 + 'Reerica'!C7 + 'Feio Lie'!C7 + Umendel!C7 + 'Fire Coast'!C7 + Yoprioq!C7 + 'Rijan bu'!C7 + Saa!C7 + 'Rinew'!C7 + Enina!C7 + Trevilla!C7 -> 1.0094211e+09 | N7: =((M7-M8)/M8) -> 0.012584589 | O7: =SUM(M7/C7) -> 0.15481785 | V7: =SUM(W7+250) -> 2010 | W7: 1760 | X7: =Aetintio!C7 + Arbiya!C7 + 'Curata'!C7 + 'Disal Nila'!C7 + Etirha!C7 + Fincen!C7 + Gaeiya!C7 + Genaire!C7 + Grazail!C7 + Guise!C7 + Laselteh!C7 + Lasri!C7 + Metndria!C7 + 'New Misos'!C7 + Peka!C7 + Pelan!C7 + Phuris!C7 + 'Raledria'!C7 + Slyiaduun!C7 + Tomscilus!C7 -> 5.0655883e+08 | Y7: =((X7-X8)/X8) -> 0.012333086 | Z7: =SUM(X7/C7) -> 0.0776924 | AG7: =SUM(AH7+250) -> 2010 | AH7: 1760 | AI7: =Acrana!C7 + Danocia!C7 + Darewa!C7 + Ealdorii!C7 + Easuhura!C7 + Eldjo!C7 + Emara!C7 + Estijan!C7 + Fermori!C7 + Ikzen!C7 + Ilicuhe!C7 + Koruch!C7 + Lycroa!C7 + Lydroa!C7 + 'Merela Sta'!C7 + 'New Kizura'!C7 + 'Niul Spijan'!C7 + Palina!C7 + Praesyu!C7 + Siana!C7 + Tonder!C7 + Ukhdari!C7 + Urbiqu!C7 + Uularin!C7 + Verusa!C7 + Yaxuto!C7 + Zenashan!C7 + Hkuqo!C7 -> 9.671313e+08 | AJ7: =((AI7-AI8)/AI8) -> 0.006808056 | AK7: =SUM(AI7/C7) -> 0.14833174 | AR7: =SUM(AS7+250) -> 2010 | AS7: 1760 | AT7: =Amcha!C7 + Byllu!C7 + 'Chaenia'!C7 + 'Cruthi Anoso'!C7 + 'Dual Cenryia'!C7 + Exilium!C7 + Galca!C7 + Inania!C7 + Inrea!C7 + Isnti!C7 + Lieri!C7 + Ocaun!C7 + Otiiric!C7 + Ozinia!C7 + Pelugrotoa!C7 + 'Rtesania'!C7 + Sadain!C7 + Selaja!C7 + Seytinemas!C7 + Sivoso!C7 + Sunsokua!C7 + Taing!C7 + Taoisia!C7 + Trian!C7 + Vayvele!C7 -> 1.3205205e+09 | AU7: =((AT7-AT8)/AT8) -> 0.0095812558 | AV7: =SUM(AT7/C7) -> 0.20253207 | BC7: =SUM(BD7+250) -> 2010 | BD7: 1760 | BE7: ='Canldives'!C7 + 'Cloja'!C7 + Dahe!C7 + Eparia!C7 + Etretes!C7 + Haiza!C7 + Ihner!C7 + Kaastini!C7 + Kusierna!C7 + Migoku!C7 + 'North Ayre'!C7 + Oscairia!C7 + Oyreain!C7 + 'Pha Hii'!C7 + 'Pruim Fijan'!C7 + 'Prystr Hii'!C7 + 'Ruylku'!C7 + Sanagara!C7 + Shinam!C7 + Stinebar!C7 + Suenan!C7 + Taval!C7 + Ucrua!C7 + Vesozata!C7 + 'Welenu Fana'!C7 + 'Western Migoku'!C7 -> 1.3413668e+09 | BF7: =((BE7-BE8)/BE8) -> 0.0072034456 | BG7: =SUM(BE7/C7) -> 0.20572932 | BN7: =SUM(BO7+250) -> 2010 | BO7: 1760 | BP7: =Andsaudare!C7 + Aplasia!C7 + Astye!C7 + 'Crila Republic'!C7 + 'Elja and Munusia'!C7 + Hiwush!C7 + Iainoa!C7 + Isari!C7 + Isuibul!C7 + Maalle!C7 + Mendereide!C7 + Nia!C7 + 'Niretui and Anulan'!C7 + Ohtina!C7 + Prstreula!C7 + 'Rethern'!C7 + 'Rkmepuia'!C7 + Tvecoca!C7 + Umarcia!C7 + 'United Delet'!C7 + Veelmit!C7 + Walporein!C7 + Yutnitu!C7 -> 2.599223e+08 | BQ7: =((BP7-BP8)/BP8) -> 0.014983889 | BR7: =SUM(BP7/C7) -> 0.039865039 | BY7: =SUM(BZ7+250) -> 2010 | BZ7: 1760 | CA7: =Ahokini!C7 + Anymna!C7 + Ashain!C7 + Baluyde!C7 + Desaki!C7 + Erkizil!C7 + 'Far Lands'!C7 + Finae!C7 + Hyelen!C7 + Iareva!C7 + Letan!C7 + 'Mesjan Hyaa'!C7 + Myla!C7 + 'Nheyes Si'!C7 + Onphello!C7 + Quidic!C7 + Shomjind!C7 + 'United Mihili'!C7 + Verste!C7 + Volver!C7 + Wundry!C7 + Yihnurda!C7 + Zhanshe!C7 + Ztesh!C7 -> 1.0957143e+09 | CB7: =((CA7-CA8)/CA8) -> 0.014481258 | CC7: =SUM(CA7/C7) -> 0.16805288
A8: =SUM(B8+250) -> 2009 | B8: 1759 | C8: =Acetoa!C8 + Acrana!C8 + Aetintio!C8 + Ahokini!C8 + Amcha!C8 + Andsaudare!C8 + Anymna!C8 + Aplasia!C8 + Arbiya!C8 + 'Areoix Lie'!C8 + Ashain!C8 + Astye!C8 + Baluyde!C8 + Byllu!C8 + 'Candenat'!C8 + 'Canldives'!C8 + 'Chaenia'!C8 + 'Cloja'!C8 + 'Crila Republic'!C8 + 'Cruthi Anoso'!C8 + 'Curata'!C8 + Dahe!C8 + Danocia!C8 + Darewa!C8 + Desaki!C8 + Deschon!C8 + 'Disal Nila'!C8 + 'Dual Cenryia'!C8 + Ealdorii!C8 + Easuhura!C8 + Eldavpir!C8 + Eldjo!C8 + 'Elja and Munusia'!C8 + Emara!C8 + Enina!C8 + Eparia!C8 + Erkizil!C8 + Estijan!C8 + Etirha!C8 + Etretes!C8 + Exilium!C8 + 'Far Lands'!C8 + 'Feio Lie'!C8 + Fermori!C8 + Finae!C8 + Fincen!C8 + 'Fire Coast'!C8 + Gaeiya!C8 + Galca!C8 + Genaire!C8 + Grazail!C8 + Guise!C8 + Haiza!C8 + Heiso!C8 + Hiwush!C8 + Hkuqo!C8 + Hyelen!C8 + Iainoa!C8 + Iareva!C8 + Ihner!C8 + Ikzen!C8 + Ilicuhe!C8 + Inania!C8 + Inrea!C8 + Iquir!C8 + Isari!C8 + Isnti!C8 + Isuibul!C8 + Jathua!C8 + Jau!C8 + Jshain!C8 + Kaastini!C8 + Koruch!C8 + Kusierna!C8 + Laselteh!C8 + Lasri!C8 + Letan!C8 + Lieri!C8 + Lycroa!C8 + Lydroa!C8 + Maalle!C8 + Mendereide!C8 + 'Merela Sta'!C8 + 'Mesjan Hyaa'!C8 + Metndria!C8 + Migoku!C8 + Myla!C8 + 'New Kizura'!C8 + 'New Misos'!C8 + 'Nheyes Si'!C8 + Nia!C8 + 'Niretui and Anulan'!C8 + 'Niul Spijan'!C8 + 'North Ayre'!C8 + Ocaun!C8 + Ohtina!C8 + Onphello!C8 + Oscairia!C8 + Othya!C8 + Otiiric!C8 + Oyreain!C8 + Ozinia!C8 + Palina!C8 + Peka!C8 + Pelan!C8 + Pelines!C8 + Pelugrotoa!C8 + 'Pha Hii'!C8 + Phuris!C8 + Praesyu!C8 + Prstreula!C8 + 'Pruim Fijan'!C8 + 'Prystr Hii'!C8 + Quidic!C8 + 'Raledria'!C8 + 'Reerica'!C8 + 'Rethern'!C8 + 'Rijan bu'!C8 + 'Rinew'!C8 + 'Rkmepuia'!C8 + 'Rtesania'!C8 + 'Ruylku'!C8 + Saa!C8 + Sadain!C8 + Sanagara!C8 + Sattle!C8 + Selaja!C8 + Seytinemas!C8 + Shinam!C8 + Shomjind!C8 + Siana!C8 + Sivoso!C8 + Slyiaduun!C8 + Stinebar!C8 + Suenan!C8 + Sunsokua!C8 + Taing!C8 + Taniduna!C8 + Taoisia!C8 + Taval!C8 + Terressin!C8 + Tomscilus!C8 + Tonder!C8 + Trevilla!C8 + Trian!C8 + Tvecoca!C8 + Ucrua!C8 + Ukhdari!C8 + Umarcia!C8 + Umendel!C8 + 'United Delet'!C8 + 'United Mihili'!C8 + Urbiqu!C8 + Uularin!C8 + Vayvele!C8 + Veelmit!C8 + Verste!C8 + Verusa!C8 + Vesozata!C8 + Viussi!C8 + Volver!C8 + Walporein!C8 + 'Welenu Fana'!C8 + 'Western Migoku'!C8 + Wundry!C8 + Yaxuto!C8 + Yihnurda!C8 + Yoprioq!C8 + Yutnitu!C8 + Zenashan!C8 + Zhanshe!C8 + Ztesh!C8 -> 6.4528494e+09 | D8: =((C8-C9)/C9) -> 0.010869919 | K8: =SUM(L8+250) -> 2009 | L8: 1759 | M8: ='Areoix Lie'!C8 + Pelines!C8 + Terressin!C8 + Taniduna!C8 + Iquir!C8 + Deschon!C8 + Othya!C8 + Eldavpir!C8 + 'Candenat'!C8 + Jau!C8 + Viussi!C8 + Jathua!C8 + Jshain!C8 + Acetoa!C8 + Sattle!C8 + 'Reerica'!C8 + 'Feio Lie'!C8 + Umendel!C8 + 'Fire Coast'!C8 + Yoprioq!C8 + 'Rijan bu'!C8 + Saa!C8 + 'Rinew'!C8 + Enina!C8 + Trevilla!C8 -> 9.9687581e+08 | N8: =((M8-M9)/M9) -> 0.012520331 | O8: =SUM(M8/C8) -> 0.15448614 | V8: =SUM(W8+250) -> 2009 | W8: 1759 | X8: =Aetintio!C8 + Arbiya!C8 + 'Curata'!C8 + 'Disal Nila'!C8 + Etirha!C8 + Fincen!C8 + Gaeiya!C8 + Genaire!C8 + Grazail!C8 + Guise!C8 + Laselteh!C8 + Lasri!C8 + Metndria!C8 + 'New Misos'!C8 + Peka!C8 + Pelan!C8 + Phuris!C8 + 'Raledria'!C8 + Slyiaduun!C8 + Tomscilus!C8 -> 5.0038751e+08 | Y8: =((X8-X9)/X9) -> 0.014921104 | Z8: =SUM(X8/C8) -> 0.077545202 | AG8: =SUM(AH8+250) -> 2009 | AH8: 1759 | AI8: =Acrana!C8 + Danocia!C8 + Darewa!C8 + Ealdorii!C8 + Easuhura!C8 + Eldjo!C8 + Emara!C8 + Estijan!C8 + Fermori!C8 + Ikzen!C8 + Ilicuhe!C8 + Koruch!C8 + Lycroa!C8 + Lydroa!C8 + 'Merela Sta'!C8 + 'New Kizura'!C8 + 'Niul Spijan'!C8 + Palina!C8 + Praesyu!C8 + Siana!C8 + Tonder!C8 + Ukhdari!C8 + Urbiqu!C8 + Uularin!C8 + Verusa!C8 + Yaxuto!C8 + Zenashan!C8 + Hkuqo!C8 -> 9.6059154e+08 | AJ8: =((AI8-AI9)/AI9) -> 0.0066885485 | AK8: =SUM(AI8/C8) -> 0.14886316 | AR8: =SUM(AS8+250) -> 2009 | AS8: 1759 | AT8: =Amcha!C8 + Byllu!C8 + 'Chaenia'!C8 + 'Cruthi Anoso'!C8 + 'Dual Cenryia'!C8 + Exilium!C8 + Galca!C8 + Inania!C8 + Inrea!C8 + Isnti!C8 + Lieri!C8 + Ocaun!C8 + Otiiric!C8 + Ozinia!C8 + Pelugrotoa!C8 + 'Rtesania'!C8 + Sadain!C8 + Selaja!C8 + Seytinemas!C8 + Sivoso!C8 + Sunsokua!C8 + Taing!C8 + Taoisia!C8 + Trian!C8 + Vayvele!C8 -> 1.3079884e+09 | AU8: =((AT8-AT9)/AT9) -> 0.010107633 | AV8: =SUM(AT8/C8) -> 0.20269935 | BC8: =SUM(BD8+250) -> 2009 | BD8: 1759 | BE8: ='Canldives'!C8 + 'Cloja'!C8 + Dahe!C8 + Eparia!C8 + Etretes!C8 + Haiza!C8 + Ihner!C8 + Kaastini!C8 + Kusierna!C8 + Migoku!C8 + 'North Ayre'!C8 + Oscairia!C8 + Oyreain!C8 + 'Pha Hii'!C8 + 'Pruim Fijan'!C8 + 'Prystr Hii'!C8 + 'Ruylku'!C8 + Sanagara!C8 + Shinam!C8 + Stinebar!C8 + Suenan!C8 + Taval!C8 + Ucrua!C8 + Vesozata!C8 + 'Welenu Fana'!C8 + 'Western Migoku'!C8 -> 1.3317734e+09 | BF8: =((BE8-BE9)/BE9) -> 0.0074987698 | BG8: =SUM(BE8/C8) -> 0.20638532 | BN8: =SUM(BO8+250) -> 2009 | BO8: 1759 | BP8: =Andsaudare!C8 + Aplasia!C8 + Astye!C8 + 'Crila Republic'!C8 + 'Elja and Munusia'!C8 + Hiwush!C8 + Iainoa!C8 + Isari!C8 + Isuibul!C8 + Maalle!C8 + Mendereide!C8 + Nia!C8 + 'Niretui and Anulan'!C8 + Ohtina!C8 + Prstreula!C8 + 'Rethern'!C8 + 'Rkmepuia'!C8 + Tvecoca!C8 + Umarcia!C8 + 'United Delet'!C8 + Veelmit!C8 + Walporein!C8 + Yutnitu!C8 -> 2.5608515e+08 | BQ8: =((BP8-BP9)/BP9) -> 0.015525571 | BR8: =SUM(BP8/C8) -> 0.039685592 | BY8: =SUM(BZ8+250) -> 2009 | BZ8: 1759 | CA8: =Ahokini!C8 + Anymna!C8 + Ashain!C8 + Baluyde!C8 + Desaki!C8 + Erkizil!C8 + 'Far Lands'!C8 + Finae!C8 + Hyelen!C8 + Iareva!C8 + Letan!C8 + 'Mesjan Hyaa'!C8 + Myla!C8 + 'Nheyes Si'!C8 + Onphello!C8 + Quidic!C8 + Shomjind!C8 + 'United Mihili'!C8 + Verste!C8 + Volver!C8 + Wundry!C8 + Yihnurda!C8 + Zhanshe!C8 + Ztesh!C8 -> 1.0800735e+09 | CB8: =((CA8-CA9)/CA9) -> 0.015097057 | CC8: =SUM(CA8/C8) -> 0.16737931
A9: =SUM(B9+250) -> 2008 | B9: 1758 | C9: =Acetoa!C9 + Acrana!C9 + Aetintio!C9 + Ahokini!C9 + Amcha!C9 + Andsaudare!C9 + Anymna!C9 + Aplasia!C9 + Arbiya!C9 + 'Areoix Lie'!C9 + Ashain!C9 + Astye!C9 + Baluyde!C9 + Byllu!C9 + 'Candenat'!C9 + 'Canldives'!C9 + 'Chaenia'!C9 + 'Cloja'!C9 + 'Crila Republic'!C9 + 'Cruthi Anoso'!C9 + 'Curata'!C9 + Dahe!C9 + Danocia!C9 + Darewa!C9 + Desaki!C9 + Deschon!C9 + 'Disal Nila'!C9 + 'Dual Cenryia'!C9 + Ealdorii!C9 + Easuhura!C9 + Eldavpir!C9 + Eldjo!C9 + 'Elja and Munusia'!C9 + Emara!C9 + Enina!C9 + Eparia!C9 + Erkizil!C9 + Estijan!C9 + Etirha!C9 + Etretes!C9 + Exilium!C9 + 'Far Lands'!C9 + 'Feio Lie'!C9 + Fermori!C9 + Finae!C9 + Fincen!C9 + 'Fire Coast'!C9 + Gaeiya!C9 + Galca!C9 + Genaire!C9 + Grazail!C9 + Guise!C9 + Haiza!C9 + Heiso!C9 + Hiwush!C9 + Hkuqo!C9 + Hyelen!C9 + Iainoa!C9 + Iareva!C9 + Ihner!C9 + Ikzen!C9 + Ilicuhe!C9 + Inania!C9 + Inrea!C9 + Iquir!C9 + Isari!C9 + Isnti!C9 + Isuibul!C9 + Jathua!C9 + Jau!C9 + Jshain!C9 + Kaastini!C9 + Koruch!C9 + Kusierna!C9 + Laselteh!C9 + Lasri!C9 + Letan!C9 + Lieri!C9 + Lycroa!C9 + Lydroa!C9 + Maalle!C9 + Mendereide!C9 + 'Merela Sta'!C9 + 'Mesjan Hyaa'!C9 + Metndria!C9 + Migoku!C9 + Myla!C9 + 'New Kizura'!C9 + 'New Misos'!C9 + 'Nheyes Si'!C9 + Nia!C9 + 'Niretui and Anulan'!C9 + 'Niul Spijan'!C9 + 'North Ayre'!C9 + Ocaun!C9 + Ohtina!C9 + Onphello!C9 + Oscairia!C9 + Othya!C9 + Otiiric!C9 + Oyreain!C9 + Ozinia!C9 + Palina!C9 + Peka!C9 + Pelan!C9 + Pelines!C9 + Pelugrotoa!C9 + 'Pha Hii'!C9 + Phuris!C9 + Praesyu!C9 + Prstreula!C9 + 'Pruim Fijan'!C9 + 'Prystr Hii'!C9 + Quidic!C9 + 'Raledria'!C9 + 'Reerica'!C9 + 'Rethern'!C9 + 'Rijan bu'!C9 + 'Rinew'!C9 + 'Rkmepuia'!C9 + 'Rtesania'!C9 + 'Ruylku'!C9 + Saa!C9 + Sadain!C9 + Sanagara!C9 + Sattle!C9 + Selaja!C9 + Seytinemas!C9 + Shinam!C9 + Shomjind!C9 + Siana!C9 + Sivoso!C9 + Slyiaduun!C9 + Stinebar!C9 + Suenan!C9 + Sunsokua!C9 + Taing!C9 + Taniduna!C9 + Taoisia!C9 + Taval!C9 + Terressin!C9 + Tomscilus!C9 + Tonder!C9 + Trevilla!C9 + Trian!C9 + Tvecoca!C9 + Ucrua!C9 + Ukhdari!C9 + Umarcia!C9 + Umendel!C9 + 'United Delet'!C9 + 'United Mihili'!C9 + Urbiqu!C9 + Uularin!C9 + Vayvele!C9 + Veelmit!C9 + Verste!C9 + Verusa!C9 + Vesozata!C9 + Viussi!C9 + Volver!C9 + Walporein!C9 + 'Welenu Fana'!C9 + 'Western Migoku'!C9 + Wundry!C9 + Yaxuto!C9 + Yihnurda!C9 + Yoprioq!C9 + Yutnitu!C9 + Zenashan!C9 + Zhanshe!C9 + Ztesh!C9 -> 6.3834617e+09 | D9: =((C9-C10)/C10) -> 0.011523894 | K9: =SUM(L9+250) -> 2008 | L9: 1758 | M9: ='Areoix Lie'!C9 + Pelines!C9 + Terressin!C9 + Taniduna!C9 + Iquir!C9 + Deschon!C9 + Othya!C9 + Eldavpir!C9 + 'Candenat'!C9 + Jau!C9 + Viussi!C9 + Jathua!C9 + Jshain!C9 + Acetoa!C9 + Sattle!C9 + 'Reerica'!C9 + 'Feio Lie'!C9 + Umendel!C9 + 'Fire Coast'!C9 + Yoprioq!C9 + 'Rijan bu'!C9 + Saa!C9 + 'Rinew'!C9 + Enina!C9 + Trevilla!C9 -> 9.8454893e+08 | N9: =((M9-M10)/M10) -> 0.015966821 | O9: =SUM(M9/C9) -> 0.15423433 | V9: =SUM(W9+250) -> 2008 | W9: 1758 | X9: =Aetintio!C9 + Arbiya!C9 + 'Curata'!C9 + 'Disal Nila'!C9 + Etirha!C9 + Fincen!C9 + Gaeiya!C9 + Genaire!C9 + Grazail!C9 + Guise!C9 + Laselteh!C9 + Lasri!C9 + Metndria!C9 + 'New Misos'!C9 + Peka!C9 + Pelan!C9 + Phuris!C9 + 'Raledria'!C9 + Slyiaduun!C9 + Tomscilus!C9 -> 4.9303094e+08 | Y9: =((X9-X10)/X10) -> 0.014651217 | Z9: =SUM(X9/C9) -> 0.07723567 | AG9: =SUM(AH9+250) -> 2008 | AH9: 1758 | AI9: =Acrana!C9 + Danocia!C9 + Darewa!C9 + Ealdorii!C9 + Easuhura!C9 + Eldjo!C9 + Emara!C9 + Estijan!C9 + Fermori!C9 + Ikzen!C9 + Ilicuhe!C9 + Koruch!C9 + Lycroa!C9 + Lydroa!C9 + 'Merela Sta'!C9 + 'New Kizura'!C9 + 'Niul Spijan'!C9 + Palina!C9 + Praesyu!C9 + Siana!C9 + Tonder!C9 + Ukhdari!C9 + Urbiqu!C9 + Uularin!C9 + Verusa!C9 + Yaxuto!C9 + Zenashan!C9 + Hkuqo!C9 -> 9.5420927e+08 | AJ9: =((AI9-AI10)/AI10) -> 0.0068699768 | AK9: =SUM(AI9/C9) -> 0.14948147 | AR9: =SUM(AS9+250) -> 2008 | AS9: 1758 | AT9: =Amcha!C9 + Byllu!C9 + 'Chaenia'!C9 + 'Cruthi Anoso'!C9 + 'Dual Cenryia'!C9 + Exilium!C9 + Galca!C9 + Inania!C9 + Inrea!C9 + Isnti!C9 + Lieri!C9 + Ocaun!C9 + Otiiric!C9 + Ozinia!C9 + Pelugrotoa!C9 + 'Rtesania'!C9 + Sadain!C9 + Selaja!C9 + Seytinemas!C9 + Sivoso!C9 + Sunsokua!C9 + Taing!C9 + Taoisia!C9 + Trian!C9 + Vayvele!C9 -> 1.2949e+09 | AU9: =((AT9-AT10)/AT10) -> 0.010108017 | AV9: =SUM(AT9/C9) -> 0.20285232 | BC9: =SUM(BD9+250) -> 2008 | BD9: 1758 | BE9: ='Canldives'!C9 + 'Cloja'!C9 + Dahe!C9 + Eparia!C9 + Etretes!C9 + Haiza!C9 + Ihner!C9 + Kaastini!C9 + Kusierna!C9 + Migoku!C9 + 'North Ayre'!C9 + Oscairia!C9 + Oyreain!C9 + 'Pha Hii'!C9 + 'Pruim Fijan'!C9 + 'Prystr Hii'!C9 + 'Ruylku'!C9 + Sanagara!C9 + Shinam!C9 + Stinebar!C9 + Suenan!C9 + Taval!C9 + Ucrua!C9 + Vesozata!C9 + 'Welenu Fana'!C9 + 'Western Migoku'!C9 -> 1.3218611e+09 | BF9: =((BE9-BE10)/BE10) -> 0.0077894278 | BG9: =SUM(BE9/C9) -> 0.2070759 | BN9: =SUM(BO9+250) -> 2008 | BO9: 1758 | BP9: =Andsaudare!C9 + Aplasia!C9 + Astye!C9 + 'Crila Republic'!C9 + 'Elja and Munusia'!C9 + Hiwush!C9 + Iainoa!C9 + Isari!C9 + Isuibul!C9 + Maalle!C9 + Mendereide!C9 + Nia!C9 + 'Niretui and Anulan'!C9 + Ohtina!C9 + Prstreula!C9 + 'Rethern'!C9 + 'Rkmepuia'!C9 + Tvecoca!C9 + Umarcia!C9 + 'United Delet'!C9 + Veelmit!C9 + Walporein!C9 + Yutnitu!C9 -> 2.5217006e+08 | BQ9: =((BP9-BP10)/BP10) -> 0.015220552 | BR9: =SUM(BP9/C9) -> 0.039503654 | BY9: =SUM(BZ9+250) -> 2008 | BZ9: 1758 | CA9: =Ahokini!C9 + Anymna!C9 + Ashain!C9 + Baluyde!C9 + Desaki!C9 + Erkizil!C9 + 'Far Lands'!C9 + Finae!C9 + Hyelen!C9 + Iareva!C9 + Letan!C9 + 'Mesjan Hyaa'!C9 + Myla!C9 + 'Nheyes Si'!C9 + Onphello!C9 + Quidic!C9 + Shomjind!C9 + 'United Mihili'!C9 + Verste!C9 + Volver!C9 + Wundry!C9 + Yihnurda!C9 + Zhanshe!C9 + Ztesh!C9 -> 1.06401e+09 | CB9: =((CA9-CA10)/CA10) -> 0.015587842 | CC9: =SUM(CA9/C9) -> 0.16668229
A10: =SUM(B10+250) -> 2007 | B10: 1757 | C10: =Acetoa!C10 + Acrana!C10 + Aetintio!C10 + Ahokini!C10 + Amcha!C10 + Andsaudare!C10 + Anymna!C10 + Aplasia!C10 + Arbiya!C10 + 'Areoix Lie'!C10 + Ashain!C10 + Astye!C10 + Baluyde!C10 + Byllu!C10 + 'Candenat'!C10 + 'Canldives'!C10 + 'Chaenia'!C10 + 'Cloja'!C10 + 'Crila Republic'!C10 + 'Cruthi Anoso'!C10 + 'Curata'!C10 + Dahe!C10 + Danocia!C10 + Darewa!C10 + Desaki!C10 + Deschon!C10 + 'Disal Nila'!C10 + 'Dual Cenryia'!C10 + Ealdorii!C10 + Easuhura!C10 + Eldavpir!C10 + Eldjo!C10 + 'Elja and Munusia'!C10 + Emara!C10 + Enina!C10 + Eparia!C10 + Erkizil!C10 + Estijan!C10 + Etirha!C10 + Etretes!C10 + Exilium!C10 + 'Far Lands'!C10 + 'Feio Lie'!C10 + Fermori!C10 + Finae!C10 + Fincen!C10 + 'Fire Coast'!C10 + Gaeiya!C10 + Galca!C10 + Genaire!C10 + Grazail!C10 + Guise!C10 + Haiza!C10 + Heiso!C10 + Hiwush!C10 + Hkuqo!C10 + Hyelen!C10 + Iainoa!C10 + Iareva!C10 + Ihner!C10 + Ikzen!C10 + Ilicuhe!C10 + Inania!C10 + Inrea!C10 + Iquir!C10 + Isari!C10 + Isnti!C10 + Isuibul!C10 + Jathua!C10 + Jau!C10 + Jshain!C10 + Kaastini!C10 + Koruch!C10 + Kusierna!C10 + Laselteh!C10 + Lasri!C10 + Letan!C10 + Lieri!C10 + Lycroa!C10 + Lydroa!C10 + Maalle!C10 + Mendereide!C10 + 'Merela Sta'!C10 + 'Mesjan Hyaa'!C10 + Metndria!C10 + Migoku!C10 + Myla!C10 + 'New Kizura'!C10 + 'New Misos'!C10 + 'Nheyes Si'!C10 + Nia!C10 + 'Niretui and Anulan'!C10 + 'Niul Spijan'!C10 + 'North Ayre'!C10 + Ocaun!C10 + Ohtina!C10 + Onphello!C10 + Oscairia!C10 + Othya!C10 + Otiiric!C10 + Oyreain!C10 + Ozinia!C10 + Palina!C10 + Peka!C10 + Pelan!C10 + Pelines!C10 + Pelugrotoa!C10 + 'Pha Hii'!C10 + Phuris!C10 + Praesyu!C10 + Prstreula!C10 + 'Pruim Fijan'!C10 + 'Prystr Hii'!C10 + Quidic!C10 + 'Raledria'!C10 + 'Reerica'!C10 + 'Rethern'!C10 + 'Rijan bu'!C10 + 'Rinew'!C10 + 'Rkmepuia'!C10 + 'Rtesania'!C10 + 'Ruylku'!C10 + Saa!C10 + Sadain!C10 + Sanagara!C10 + Sattle!C10 + Selaja!C10 + Seytinemas!C10 + Shinam!C10 + Shomjind!C10 + Siana!C10 + Sivoso!C10 + Slyiaduun!C10 + Stinebar!C10 + Suenan!C10 + Sunsokua!C10 + Taing!C10 + Taniduna!C10 + Taoisia!C10 + Taval!C10 + Terressin!C10 + Tomscilus!C10 + Tonder!C10 + Trevilla!C10 + Trian!C10 + Tvecoca!C10 + Ucrua!C10 + Ukhdari!C10 + Umarcia!C10 + Umendel!C10 + 'United Delet'!C10 + 'United Mihili'!C10 + Urbiqu!C10 + Uularin!C10 + Vayvele!C10 + Veelmit!C10 + Verste!C10 + Verusa!C10 + Vesozata!C10 + Viussi!C10 + Volver!C10 + Walporein!C10 + 'Welenu Fana'!C10 + 'Western Migoku'!C10 + Wundry!C10 + Yaxuto!C10 + Yihnurda!C10 + Yoprioq!C10 + Yutnitu!C10 + Zenashan!C10 + Zhanshe!C10 + Ztesh!C10 -> 6.3107374e+09 | D10: =((C10-C11)/C11) -> 0.011187138 | K10: =SUM(L10+250) -> 2007 | L10: 1757 | M10: ='Areoix Lie'!C10 + Pelines!C10 + Terressin!C10 + Taniduna!C10 + Iquir!C10 + Deschon!C10 + Othya!C10 + Eldavpir!C10 + 'Candenat'!C10 + Jau!C10 + Viussi!C10 + Jathua!C10 + Jshain!C10 + Acetoa!C10 + Sattle!C10 + 'Reerica'!C10 + 'Feio Lie'!C10 + Umendel!C10 + 'Fire Coast'!C10 + Yoprioq!C10 + 'Rijan bu'!C10 + Saa!C10 + 'Rinew'!C10 + Enina!C10 + Trevilla!C10 -> 9.6907587e+08 | N10: =((M10-M11)/M11) -> 0.013427115 | O10: =SUM(M10/C10) -> 0.15355985 | V10: =SUM(W10+250) -> 2007 | W10: 1757 | X10: =Aetintio!C10 + Arbiya!C10 + 'Curata'!C10 + 'Disal Nila'!C10 + Etirha!C10 + Fincen!C10 + Gaeiya!C10 + Genaire!C10 + Grazail!C10 + Guise!C10 + Laselteh!C10 + Lasri!C10 + Metndria!C10 + 'New Misos'!C10 + Peka!C10 + Pelan!C10 + Phuris!C10 + 'Raledria'!C10 + Slyiaduun!C10 + Tomscilus!C10 -> 4.8591174e+08 | Y10: =((X10-X11)/X11) -> 0.013756286 | Z10: =SUM(X10/C10) -> 0.076997617 | AG10: =SUM(AH10+250) -> 2007 | AH10: 1757 | AI10: =Acrana!C10 + Danocia!C10 + Darewa!C10 + Ealdorii!C10 + Easuhura!C10 + Eldjo!C10 + Emara!C10 + Estijan!C10 + Fermori!C10 + Ikzen!C10 + Ilicuhe!C10 + Koruch!C10 + Lycroa!C10 + Lydroa!C10 + 'Merela Sta'!C10 + 'New Kizura'!C10 + 'Niul Spijan'!C10 + Palina!C10 + Praesyu!C10 + Siana!C10 + Tonder!C10 + Ukhdari!C10 + Urbiqu!C10 + Uularin!C10 + Verusa!C10 + Yaxuto!C10 + Zenashan!C10 + Hkuqo!C10 -> 9.476986e+08 | AJ10: =((AI10-AI11)/AI11) -> 0.0066946751 | AK10: =SUM(AI10/C10) -> 0.1501724 | AR10: =SUM(AS10+250) -> 2007 | AS10: 1757 | AT10: =Amcha!C10 + Byllu!C10 + 'Chaenia'!C10 + 'Cruthi Anoso'!C10 + 'Dual Cenryia'!C10 + Exilium!C10 + Galca!C10 + Inania!C10 + Inrea!C10 + Isnti!C10 + Lieri!C10 + Ocaun!C10 + Otiiric!C10 + Ozinia!C10 + Pelugrotoa!C10 + 'Rtesania'!C10 + Sadain!C10 + Selaja!C10 + Seytinemas!C10 + Sivoso!C10 + Sunsokua!C10 + Taing!C10 + Taoisia!C10 + Trian!C10 + Vayvele!C10 -> 1.2819421e+09 | AU10: =((AT10-AT11)/AT11) -> 0.010144304 | AV10: =SUM(AT10/C10) -> 0.20313666 | BC10: =SUM(BD10+250) -> 2007 | BD10: 1757 | BE10: ='Canldives'!C10 + 'Cloja'!C10 + Dahe!C10 + Eparia!C10 + Etretes!C10 + Haiza!C10 + Ihner!C10 + Kaastini!C10 + Kusierna!C10 + Migoku!C10 + 'North Ayre'!C10 + Oscairia!C10 + Oyreain!C10 + 'Pha Hii'!C10 + 'Pruim Fijan'!C10 + 'Prystr Hii'!C10 + 'Ruylku'!C10 + Sanagara!C10 + Shinam!C10 + Stinebar!C10 + Suenan!C10 + Taval!C10 + Ucrua!C10 + Vesozata!C10 + 'Welenu Fana'!C10 + 'Western Migoku'!C10 -> 1.3116441e+09 | BF10: =((BE10-BE11)/BE11) -> 0.0081378018 | BG10: =SUM(BE10/C10) -> 0.20784324 | BN10: =SUM(BO10+250) -> 2007 | BO10: 1757 | BP10: =Andsaudare!C10 + Aplasia!C10 + Astye!C10 + 'Crila Republic'!C10 + 'Elja and Munusia'!C10 + Hiwush!C10 + Iainoa!C10 + Isari!C10 + Isuibul!C10 + Maalle!C10 + Mendereide!C10 + Nia!C10 + 'Niretui and Anulan'!C10 + Ohtina!C10 + Prstreula!C10 + 'Rethern'!C10 + 'Rkmepuia'!C10 + Tvecoca!C10 + Umarcia!C10 + 'United Delet'!C10 + Veelmit!C10 + Walporein!C10 + Yutnitu!C10 -> 2.4838944e+08 | BQ10: =((BP10-BP11)/BP11) -> 0.015184271 | BR10: =SUM(BP10/C10) -> 0.039359812 | BY10: =SUM(BZ10+250) -> 2007 | BZ10: 1757 | CA10: =Ahokini!C10 + Anymna!C10 + Ashain!C10 + Baluyde!C10 + Desaki!C10 + Erkizil!C10 + 'Far Lands'!C10 + Finae!C10 + Hyelen!C10 + Iareva!C10 + Letan!C10 + 'Mesjan Hyaa'!C10 + Myla!C10 + 'Nheyes Si'!C10 + Onphello!C10 + Quidic!C10 + Shomjind!C10 + 'United Mihili'!C10 + Verste!C10 + Volver!C10 + Wundry!C10 + Yihnurda!C10 + Zhanshe!C10 + Ztesh!C10 -> 1.047679e+09 | CB10: =((CA10-CA11)/CA11) -> 0.016082189 | CC10: =SUM(CA10/C10) -> 0.1660153
A11: =SUM(B11+250) -> 2006 | B11: 1756 | C11: =Acetoa!C11 + Acrana!C11 + Aetintio!C11 + Ahokini!C11 + Amcha!C11 + Andsaudare!C11 + Anymna!C11 + Aplasia!C11 + Arbiya!C11 + 'Areoix Lie'!C11 + Ashain!C11 + Astye!C11 + Baluyde!C11 + Byllu!C11 + 'Candenat'!C11 + 'Canldives'!C11 + 'Chaenia'!C11 + 'Cloja'!C11 + 'Crila Republic'!C11 + 'Cruthi Anoso'!C11 + 'Curata'!C11 + Dahe!C11 + Danocia!C11 + Darewa!C11 + Desaki!C11 + Deschon!C11 + 'Disal Nila'!C11 + 'Dual Cenryia'!C11 + Ealdorii!C11 + Easuhura!C11 + Eldavpir!C11 + Eldjo!C11 + 'Elja and Munusia'!C11 + Emara!C11 + Enina!C11 + Eparia!C11 + Erkizil!C11 + Estijan!C11 + Etirha!C11 + Etretes!C11 + Exilium!C11 + 'Far Lands'!C11 + 'Feio Lie'!C11 + Fermori!C11 + Finae!C11 + Fincen!C11 + 'Fire Coast'!C11 + Gaeiya!C11 + Galca!C11 + Genaire!C11 + Grazail!C11 + Guise!C11 + Haiza!C11 + Heiso!C11 + Hiwush!C11 + Hkuqo!C11 + Hyelen!C11 + Iainoa!C11 + Iareva!C11 + Ihner!C11 + Ikzen!C11 + Ilicuhe!C11 + Inania!C11 + Inrea!C11 + Iquir!C11 + Isari!C11 + Isnti!C11 + Isuibul!C11 + Jathua!C11 + Jau!C11 + Jshain!C11 + Kaastini!C11 + Koruch!C11 + Kusierna!C11 + Laselteh!C11 + Lasri!C11 + Letan!C11 + Lieri!C11 + Lycroa!C11 + Lydroa!C11 + Maalle!C11 + Mendereide!C11 + 'Merela Sta'!C11 + 'Mesjan Hyaa'!C11 + Metndria!C11 + Migoku!C11 + Myla!C11 + 'New Kizura'!C11 + 'New Misos'!C11 + 'Nheyes Si'!C11 + Nia!C11 + 'Niretui and Anulan'!C11 + 'Niul Spijan'!C11 + 'North Ayre'!C11 + Ocaun!C11 + Ohtina!C11 + Onphello!C11 + Oscairia!C11 + Othya!C11 + Otiiric!C11 + Oyreain!C11 + Ozinia!C11 + Palina!C11 + Peka!C11 + Pelan!C11 + Pelines!C11 + Pelugrotoa!C11 + 'Pha Hii'!C11 + Phuris!C11 + Praesyu!C11 + Prstreula!C11 + 'Pruim Fijan'!C11 + 'Prystr Hii'!C11 + Quidic!C11 + 'Raledria'!C11 + 'Reerica'!C11 + 'Rethern'!C11 + 'Rijan bu'!C11 + 'Rinew'!C11 + 'Rkmepuia'!C11 + 'Rtesania'!C11 + 'Ruylku'!C11 + Saa!C11 + Sadain!C11 + Sanagara!C11 + Sattle!C11 + Selaja!C11 + Seytinemas!C11 + Shinam!C11 + Shomjind!C11 + Siana!C11 + Sivoso!C11 + Slyiaduun!C11 + Stinebar!C11 + Suenan!C11 + Sunsokua!C11 + Taing!C11 + Taniduna!C11 + Taoisia!C11 + Taval!C11 + Terressin!C11 + Tomscilus!C11 + Tonder!C11 + Trevilla!C11 + Trian!C11 + Tvecoca!C11 + Ucrua!C11 + Ukhdari!C11 + Umarcia!C11 + Umendel!C11 + 'United Delet'!C11 + 'United Mihili'!C11 + Urbiqu!C11 + Uularin!C11 + Vayvele!C11 + Veelmit!C11 + Verste!C11 + Verusa!C11 + Vesozata!C11 + Viussi!C11 + Volver!C11 + Walporein!C11 + 'Welenu Fana'!C11 + 'Western Migoku'!C11 + Wundry!C11 + Yaxuto!C11 + Yihnurda!C11 + Yoprioq!C11 + Yutnitu!C11 + Zenashan!C11 + Zhanshe!C11 + Ztesh!C11 -> 6.2409194e+09 | D11: =((C11-C12)/C12) -> 0.011344612 | K11: =SUM(L11+250) -> 2006 | L11: 1756 | M11: ='Areoix Lie'!C11 + Pelines!C11 + Terressin!C11 + Taniduna!C11 + Iquir!C11 + Deschon!C11 + Othya!C11 + Eldavpir!C11 + 'Candenat'!C11 + Jau!C11 + Viussi!C11 + Jathua!C11 + Jshain!C11 + Acetoa!C11 + Sattle!C11 + 'Reerica'!C11 + 'Feio Lie'!C11 + Umendel!C11 + 'Fire Coast'!C11 + Yoprioq!C11 + 'Rijan bu'!C11 + Saa!C11 + 'Rinew'!C11 + Enina!C11 + Trevilla!C11 -> 9.5623637e+08 | N11: =((M11-M12)/M12) -> 0.014195436 | O11: =SUM(M11/C11) -> 0.15322043 | V11: =SUM(W11+250) -> 2006 | W11: 1756 | X11: =Aetintio!C11 + Arbiya!C11 + 'Curata'!C11 + 'Disal Nila'!C11 + Etirha!C11 + Fincen!C11 + Gaeiya!C11 + Genaire!C11 + Grazail!C11 + Guise!C11 + Laselteh!C11 + Lasri!C11 + Metndria!C11 + 'New Misos'!C11 + Peka!C11 + Pelan!C11 + Phuris!C11 + 'Raledria'!C11 + Slyiaduun!C11 + Tomscilus!C11 -> 4.7931811e+08 | Y11: =((X11-X12)/X12) -> 0.011184981 | Z11: =SUM(X11/C11) -> 0.076802483 | AG11: =SUM(AH11+250) -> 2006 | AH11: 1756 | AI11: =Acrana!C11 + Danocia!C11 + Darewa!C11 + Ealdorii!C11 + Easuhura!C11 + Eldjo!C11 + Emara!C11 + Estijan!C11 + Fermori!C11 + Ikzen!C11 + Ilicuhe!C11 + Koruch!C11 + Lycroa!C11 + Lydroa!C11 + 'Merela Sta'!C11 + 'New Kizura'!C11 + 'Niul Spijan'!C11 + Palina!C11 + Praesyu!C11 + Siana!C11 + Tonder!C11 + Ukhdari!C11 + Urbiqu!C11 + Uularin!C11 + Verusa!C11 + Yaxuto!C11 + Zenashan!C11 + Hkuqo!C11 -> 9.4139626e+08 | AJ11: =((AI11-AI12)/AI12) -> 0.0070115451 | AK11: =SUM(AI11/C11) -> 0.15084256 | AR11: =SUM(AS11+250) -> 2006 | AS11: 1756 | AT11: =Amcha!C11 + Byllu!C11 + 'Chaenia'!C11 + 'Cruthi Anoso'!C11 + 'Dual Cenryia'!C11 + Exilium!C11 + Galca!C11 + Inania!C11 + Inrea!C11 + Isnti!C11 + Lieri!C11 + Ocaun!C11 + Otiiric!C11 + Ozinia!C11 + Pelugrotoa!C11 + 'Rtesania'!C11 + Sadain!C11 + Selaja!C11 + Seytinemas!C11 + Sivoso!C11 + Sunsokua!C11 + Taing!C11 + Taoisia!C11 + Trian!C11 + Vayvele!C11 -> 1.2690683e+09 | AU11: =((AT11-AT12)/AT12) -> 0.010942699 | AV11: =SUM(AT11/C11) -> 0.20334637 | BC11: =SUM(BD11+250) -> 2006 | BD11: 1756 | BE11: ='Canldives'!C11 + 'Cloja'!C11 + Dahe!C11 + Eparia!C11 + Etretes!C11 + Haiza!C11 + Ihner!C11 + Kaastini!C11 + Kusierna!C11 + Migoku!C11 + 'North Ayre'!C11 + Oscairia!C11 + Oyreain!C11 + 'Pha Hii'!C11 + 'Pruim Fijan'!C11 + 'Prystr Hii'!C11 + 'Ruylku'!C11 + Sanagara!C11 + Shinam!C11 + Stinebar!C11 + Suenan!C11 + Taval!C11 + Ucrua!C11 + Vesozata!C11 + 'Welenu Fana'!C11 + 'Western Migoku'!C11 -> 1.3010564e+09 | BF11: =((BE11-BE12)/BE12) -> 0.0082471155 | BG11: =SUM(BE11/C11) -> 0.20847191 | BN11: =SUM(BO11+250) -> 2006 | BO11: 1756 | BP11: =Andsaudare!C11 + Aplasia!C11 + Astye!C11 + 'Crila Republic'!C11 + 'Elja and Munusia'!C11 + Hiwush!C11 + Iainoa!C11 + Isari!C11 + Isuibul!C11 + Maalle!C11 + Mendereide!C11 + Nia!C11 + 'Niretui and Anulan'!C11 + Ohtina!C11 + Prstreula!C11 + 'Rethern'!C11 + 'Rkmepuia'!C11 + Tvecoca!C11 + Umarcia!C11 + 'United Delet'!C11 + Veelmit!C11 + Walporein!C11 + Yutnitu!C11 -> 2.4467424e+08 | BQ11: =((BP11-BP12)/BP12) -> 0.015075399 | BR11: =SUM(BP11/C11) -> 0.039204839 | BY11: =SUM(BZ11+250) -> 2006 | BZ11: 1756 | CA11: =Ahokini!C11 + Anymna!C11 + Ashain!C11 + Baluyde!C11 + Desaki!C11 + Erkizil!C11 + 'Far Lands'!C11 + Finae!C11 + Hyelen!C11 + Iareva!C11 + Letan!C11 + 'Mesjan Hyaa'!C11 + Myla!C11 + 'Nheyes Si'!C11 + Onphello!C11 + Quidic!C11 + Shomjind!C11 + 'United Mihili'!C11 + Verste!C11 + Volver!C11 + Wundry!C11 + Yihnurda!C11 + Zhanshe!C11 + Ztesh!C11 -> 1.0310967e+09 | CB11: =((CA11-CA12)/CA12) -> 0.016204865 | CC11: =SUM(CA11/C11) -> 0.16521551
